2021-09-09 15:04:14,652 - Уровень INFO в executor.py._welcome: Bot: CyberEvil [@cyber_evil_bot]
2021-09-09 15:04:16,224 - Уровень WARNING в executor.py._skip_updates: Updates were skipped successfully.
2021-09-09 15:05:14,542 - Уровень INFO в logging.py.on_pre_process_message: Received message [ID:1150] in chat [private:482930388]
2021-09-09 15:05:16,778 - Уровень INFO в logging.py.on_post_process_update: Process update [ID:88022729]: [success] (in 2236 ms)
2021-09-09 15:05:16,779 - Уровень INFO в web_log.py.log: 127.0.0.1 [09/Sep/2021:12:05:14 +0000] "POST / HTTP/1.1" 200 158 "-" "-"
2021-09-09 15:05:47,556 - Уровень INFO в logging.py.on_pre_process_message: Received message [ID:1152] in chat [private:482930388]
2021-09-09 15:05:48,660 - Уровень INFO в logging.py.on_post_process_update: Process update [ID:88022730]: [success] (in 1103 ms)
2021-09-09 15:05:49,908 - Уровень INFO в web_log.py.log: 127.0.0.1 [09/Sep/2021:12:05:47 +0000] "POST / HTTP/1.1" 200 158 "-" "-"
2021-09-09 15:05:59,864 - Уровень INFO в logging.py.on_pre_process_message: Received message [ID:1155] in chat [private:482930388]
2021-09-09 15:06:00,080 - Уровень INFO в logging.py.on_post_process_update: Process update [ID:88022731]: [success] (in 217 ms)
2021-09-09 15:06:00,085 - Уровень INFO в web_log.py.log: 127.0.0.1 [09/Sep/2021:12:05:59 +0000] "POST / HTTP/1.1" 200 158 "-" "-"
2021-09-09 15:06:07,217 - Уровень INFO в logging.py.on_pre_process_message: Received message [ID:1157] in chat [private:482930388]
2021-09-09 15:06:07,433 - Уровень INFO в logging.py.on_post_process_update: Process update [ID:88022732]: [success] (in 215 ms)
2021-09-09 15:06:07,434 - Уровень INFO в web_log.py.log: 127.0.0.1 [09/Sep/2021:12:06:07 +0000] "POST / HTTP/1.1" 200 158 "-" "-"
2021-09-09 15:06:53,360 - Уровень INFO в executor.py._welcome: Bot: CyberEvil [@cyber_evil_bot]
2021-09-09 15:06:54,844 - Уровень WARNING в executor.py._skip_updates: Updates were skipped successfully.
2021-09-09 15:07:07,574 - Уровень INFO в logging.py.on_pre_process_message: Received message [ID:1159] in chat [private:482930388]
2021-09-09 15:07:07,751 - Уровень INFO в logging.py.on_post_process_update: Process update [ID:88022733]: [success] (in 177 ms)
2021-09-09 15:07:07,753 - Уровень INFO в web_log.py.log: 127.0.0.1 [09/Sep/2021:12:07:07 +0000] "POST / HTTP/1.1" 200 158 "-" "-"
2021-09-09 15:07:41,371 - Уровень INFO в logging.py.on_pre_process_message: Received message [ID:1161] in chat [private:482930388]
2021-09-09 15:07:42,731 - Уровень INFO в logging.py.on_post_process_update: Process update [ID:88022734]: [success] (in 1360 ms)
2021-09-09 15:07:42,739 - Уровень INFO в web_log.py.log: 127.0.0.1 [09/Sep/2021:12:07:41 +0000] "POST / HTTP/1.1" 200 158 "-" "-"
2021-09-09 15:07:47,380 - Уровень INFO в logging.py.on_pre_process_message: Received message [ID:1163] in chat [private:482930388]
2021-09-09 15:07:47,598 - Уровень INFO в logging.py.on_post_process_update: Process update [ID:88022735]: [success] (in 218 ms)
2021-09-09 15:07:47,600 - Уровень INFO в web_log.py.log: 127.0.0.1 [09/Sep/2021:12:07:46 +0000] "POST / HTTP/1.1" 200 158 "-" "-"
2021-09-09 15:07:49,714 - Уровень INFO в logging.py.on_pre_process_message: Received message [ID:1165] in chat [private:482930388]
2021-09-09 15:07:49,904 - Уровень INFO в logging.py.on_post_process_update: Process update [ID:88022736]: [success] (in 190 ms)
2021-09-09 15:07:49,906 - Уровень INFO в web_log.py.log: 127.0.0.1 [09/Sep/2021:12:07:49 +0000] "POST / HTTP/1.1" 200 158 "-" "-"
2021-09-09 15:08:50,826 - Уровень INFO в executor.py._welcome: Bot: CyberEvil [@cyber_evil_bot]
2021-09-09 15:08:52,360 - Уровень WARNING в executor.py._skip_updates: Updates were skipped successfully.
2021-09-09 15:09:24,126 - Уровень INFO в executor.py._welcome: Bot: CyberEvil [@cyber_evil_bot]
2021-09-09 15:09:28,812 - Уровень INFO в executor.py._welcome: Bot: CyberEvil [@cyber_evil_bot]
2021-09-09 15:09:30,293 - Уровень WARNING в executor.py._skip_updates: Updates were skipped successfully.
2021-09-09 15:09:40,962 - Уровень INFO в logging.py.on_pre_process_message: Received message [ID:1167] in chat [private:482930388]
2021-09-09 15:09:41,197 - Уровень INFO в logging.py.on_post_process_update: Process update [ID:88022737]: [success] (in 235 ms)
2021-09-09 15:09:41,198 - Уровень INFO в web_log.py.log: 127.0.0.1 [09/Sep/2021:12:09:40 +0000] "POST / HTTP/1.1" 200 158 "-" "-"
2021-09-09 15:09:43,338 - Уровень INFO в logging.py.on_pre_process_message: Received message [ID:1169] in chat [private:482930388]
2021-09-09 15:09:43,532 - Уровень INFO в logging.py.on_post_process_update: Process update [ID:88022738]: [success] (in 194 ms)
2021-09-09 15:09:43,533 - Уровень INFO в web_log.py.log: 127.0.0.1 [09/Sep/2021:12:09:43 +0000] "POST / HTTP/1.1" 200 158 "-" "-"
2021-09-10 09:35:07,737 - Уровень INFO в executor.py._welcome: Bot: CyberEvil [@cyber_evil_bot]
2021-09-10 09:35:09,191 - Уровень WARNING в executor.py._skip_updates: Updates were skipped successfully.
2021-09-10 09:36:40,470 - Уровень INFO в executor.py._welcome: Bot: CyberEvil [@cyber_evil_bot]
2021-09-10 09:36:41,934 - Уровень WARNING в executor.py._skip_updates: Updates were skipped successfully.
2021-09-10 09:37:06,950 - Уровень INFO в logging.py.on_pre_process_message: Received message [ID:1171] in chat [private:482930388]
2021-09-10 09:37:07,866 - Уровень INFO в logging.py.on_post_process_update: Process update [ID:88022739]: [success] (in 915 ms)
2021-09-10 09:37:07,867 - Уровень INFO в web_log.py.log: 127.0.0.1 [10/Sep/2021:06:37:06 +0000] "POST / HTTP/1.1" 200 158 "-" "-"
2021-09-10 09:37:10,826 - Уровень INFO в logging.py.on_pre_process_message: Received message [ID:1173] in chat [private:482930388]
2021-09-10 09:37:11,082 - Уровень INFO в logging.py.on_post_process_update: Process update [ID:88022740]: [success] (in 256 ms)
2021-09-10 09:37:11,083 - Уровень INFO в web_log.py.log: 127.0.0.1 [10/Sep/2021:06:37:10 +0000] "POST / HTTP/1.1" 200 158 "-" "-"
2021-09-10 09:40:16,168 - Уровень INFO в executor.py._welcome: Bot: CyberEvil [@cyber_evil_bot]
2021-09-10 09:40:17,638 - Уровень WARNING в executor.py._skip_updates: Updates were skipped successfully.
2021-09-10 09:40:34,527 - Уровень INFO в logging.py.on_pre_process_message: Received message [ID:1175] in chat [private:482930388]
2021-09-10 09:40:35,744 - Уровень INFO в logging.py.on_post_process_update: Process update [ID:88022741]: [success] (in 1217 ms)
2021-09-10 09:40:35,746 - Уровень INFO в web_log.py.log: 127.0.0.1 [10/Sep/2021:06:40:34 +0000] "POST / HTTP/1.1" 200 158 "-" "-"
2021-09-10 09:40:37,725 - Уровень INFO в logging.py.on_pre_process_message: Received message [ID:1177] in chat [private:482930388]
2021-09-10 09:40:37,920 - Уровень INFO в logging.py.on_post_process_update: Process update [ID:88022742]: [success] (in 196 ms)
2021-09-10 09:40:37,921 - Уровень INFO в web_log.py.log: 127.0.0.1 [10/Sep/2021:06:40:37 +0000] "POST / HTTP/1.1" 200 158 "-" "-"
2021-09-10 09:40:39,349 - Уровень INFO в logging.py.on_pre_process_message: Received message [ID:1179] in chat [private:482930388]
2021-09-10 09:40:39,521 - Уровень INFO в logging.py.on_post_process_update: Process update [ID:88022743]: [success] (in 172 ms)
2021-09-10 09:40:39,522 - Уровень INFO в web_log.py.log: 127.0.0.1 [10/Sep/2021:06:40:39 +0000] "POST / HTTP/1.1" 200 158 "-" "-"
2021-09-10 09:40:40,268 - Уровень INFO в logging.py.on_pre_process_message: Received message [ID:1181] in chat [private:482930388]
2021-09-10 09:40:40,453 - Уровень INFO в logging.py.on_post_process_update: Process update [ID:88022744]: [success] (in 186 ms)
2021-09-10 09:40:40,455 - Уровень INFO в web_log.py.log: 127.0.0.1 [10/Sep/2021:06:40:40 +0000] "POST / HTTP/1.1" 200 158 "-" "-"
2021-09-10 09:40:41,393 - Уровень INFO в logging.py.on_pre_process_message: Received message [ID:1183] in chat [private:482930388]
2021-09-10 09:40:42,296 - Уровень INFO в logging.py.on_post_process_update: Process update [ID:88022745]: [success] (in 903 ms)
2021-09-10 09:40:42,299 - Уровень INFO в web_log.py.log: 127.0.0.1 [10/Sep/2021:06:40:41 +0000] "POST / HTTP/1.1" 200 158 "-" "-"
2021-09-10 09:44:00,038 - Уровень INFO в executor.py._welcome: Bot: CyberEvil [@cyber_evil_bot]
2021-09-10 09:44:01,543 - Уровень WARNING в executor.py._skip_updates: Updates were skipped successfully.
2021-09-10 09:44:15,598 - Уровень INFO в logging.py.on_pre_process_message: Received message [ID:1185] in chat [private:482930388]
2021-09-10 09:44:15,793 - Уровень INFO в logging.py.on_post_process_update: Process update [ID:88022746]: [success] (in 196 ms)
2021-09-10 09:44:15,796 - Уровень INFO в web_log.py.log: 127.0.0.1 [10/Sep/2021:06:44:15 +0000] "POST / HTTP/1.1" 200 158 "-" "-"
2021-09-10 09:46:40,115 - Уровень INFO в executor.py._welcome: Bot: CyberEvil [@cyber_evil_bot]
2021-09-10 09:46:41,563 - Уровень WARNING в executor.py._skip_updates: Updates were skipped successfully.
2021-09-10 09:46:47,441 - Уровень INFO в logging.py.on_pre_process_message: Received message [ID:1187] in chat [private:482930388]
2021-09-10 09:46:47,633 - Уровень INFO в logging.py.on_post_process_update: Process update [ID:88022747]: [success] (in 194 ms)
2021-09-10 09:46:47,634 - Уровень INFO в web_log.py.log: 127.0.0.1 [10/Sep/2021:06:46:47 +0000] "POST / HTTP/1.1" 200 158 "-" "-"
2021-09-10 09:47:02,052 - Уровень INFO в logging.py.on_pre_process_message: Received message [ID:1189] in chat [private:482930388]
2021-09-10 09:47:02,229 - Уровень INFO в logging.py.on_post_process_update: Process update [ID:88022748]: [success] (in 177 ms)
2021-09-10 09:47:02,230 - Уровень INFO в web_log.py.log: 127.0.0.1 [10/Sep/2021:06:47:02 +0000] "POST / HTTP/1.1" 200 158 "-" "-"
2021-09-10 09:47:07,821 - Уровень INFO в logging.py.on_pre_process_message: Received message [ID:1191] in chat [private:482930388]
2021-09-10 09:47:08,020 - Уровень INFO в logging.py.on_post_process_update: Process update [ID:88022749]: [success] (in 199 ms)
2021-09-10 09:47:08,023 - Уровень INFO в web_log.py.log: 127.0.0.1 [10/Sep/2021:06:47:07 +0000] "POST / HTTP/1.1" 200 158 "-" "-"
2021-09-10 09:47:10,236 - Уровень INFO в logging.py.on_pre_process_message: Received message [ID:1193] in chat [private:482930388]
2021-09-10 09:47:10,477 - Уровень INFO в logging.py.on_post_process_update: Process update [ID:88022750]: [success] (in 241 ms)
2021-09-10 09:47:10,481 - Уровень INFO в web_log.py.log: 127.0.0.1 [10/Sep/2021:06:47:10 +0000] "POST / HTTP/1.1" 200 158 "-" "-"
2021-09-10 09:53:33,377 - Уровень INFO в executor.py._welcome: Bot: CyberEvil [@cyber_evil_bot]
2021-09-10 09:53:34,829 - Уровень WARNING в executor.py._skip_updates: Updates were skipped successfully.
2021-09-10 13:18:13,340 - Уровень INFO в executor.py._welcome: Bot: CyberEvil [@cyber_evil_bot]
2021-09-10 13:18:14,980 - Уровень WARNING в executor.py._skip_updates: Updates were skipped successfully.
2021-09-10 13:18:45,080 - Уровень INFO в logging.py.on_pre_process_message: Received message [ID:1195] in chat [private:482930388]
2021-09-10 13:18:46,002 - Уровень INFO в logging.py.on_post_process_update: Process update [ID:88022751]: [success] (in 922 ms)
2021-09-10 13:18:46,004 - Уровень INFO в web_log.py.log: 127.0.0.1 [10/Sep/2021:10:18:45 +0000] "POST / HTTP/1.1" 200 158 "-" "-"
2021-09-10 13:18:47,554 - Уровень INFO в logging.py.on_pre_process_message: Received message [ID:1197] in chat [private:482930388]
2021-09-10 13:18:47,747 - Уровень INFO в logging.py.on_post_process_update: Process update [ID:88022752]: [success] (in 194 ms)
2021-09-10 13:18:47,749 - Уровень INFO в web_log.py.log: 127.0.0.1 [10/Sep/2021:10:18:47 +0000] "POST / HTTP/1.1" 200 158 "-" "-"
2021-09-10 13:18:51,320 - Уровень INFO в logging.py.on_pre_process_message: Received message [ID:1199] in chat [private:482930388]
2021-09-10 13:18:51,495 - Уровень INFO в logging.py.on_post_process_update: Process update [ID:88022753]: [success] (in 175 ms)
2021-09-10 13:18:51,497 - Уровень INFO в web_log.py.log: 127.0.0.1 [10/Sep/2021:10:18:51 +0000] "POST / HTTP/1.1" 200 158 "-" "-"
2021-09-10 13:18:52,910 - Уровень INFO в logging.py.on_pre_process_message: Received message [ID:1201] in chat [private:482930388]
2021-09-10 13:18:53,097 - Уровень INFO в logging.py.on_post_process_update: Process update [ID:88022754]: [success] (in 187 ms)
2021-09-10 13:18:53,103 - Уровень INFO в web_log.py.log: 127.0.0.1 [10/Sep/2021:10:18:52 +0000] "POST / HTTP/1.1" 200 158 "-" "-"
2021-09-10 13:18:54,721 - Уровень INFO в logging.py.on_pre_process_message: Received message [ID:1203] in chat [private:482930388]
2021-09-10 13:18:55,294 - Уровень INFO в logging.py.on_post_process_update: Process update [ID:88022755]: [success] (in 573 ms)
2021-09-10 13:18:55,295 - Уровень INFO в web_log.py.log: 127.0.0.1 [10/Sep/2021:10:18:54 +0000] "POST / HTTP/1.1" 200 158 "-" "-"
2021-09-10 13:18:56,308 - Уровень INFO в logging.py.on_pre_process_message: Received message [ID:1205] in chat [private:482930388]
2021-09-10 13:18:56,538 - Уровень INFO в logging.py.on_post_process_update: Process update [ID:88022756]: [success] (in 231 ms)
2021-09-10 13:18:56,540 - Уровень INFO в web_log.py.log: 127.0.0.1 [10/Sep/2021:10:18:56 +0000] "POST / HTTP/1.1" 200 158 "-" "-"
2021-09-10 13:18:57,861 - Уровень INFO в logging.py.on_pre_process_message: Received message [ID:1207] in chat [private:482930388]
2021-09-10 13:18:58,089 - Уровень INFO в logging.py.on_post_process_update: Process update [ID:88022757]: [success] (in 228 ms)
2021-09-10 13:18:58,092 - Уровень INFO в web_log.py.log: 127.0.0.1 [10/Sep/2021:10:18:57 +0000] "POST / HTTP/1.1" 200 158 "-" "-"
2021-09-10 13:19:13,226 - Уровень INFO в logging.py.on_pre_process_message: Received message [ID:1209] in chat [private:482930388]
2021-09-10 13:19:14,537 - Уровень INFO в logging.py.on_post_process_update: Process update [ID:88022758]: [success] (in 1311 ms)
2021-09-10 13:19:14,538 - Уровень INFO в web_log.py.log: 127.0.0.1 [10/Sep/2021:10:19:13 +0000] "POST / HTTP/1.1" 200 158 "-" "-"
2021-09-10 13:19:19,566 - Уровень INFO в logging.py.on_pre_process_message: Received message [ID:1211] in chat [private:482930388]
2021-09-10 13:19:19,765 - Уровень INFO в logging.py.on_post_process_update: Process update [ID:88022759]: [success] (in 199 ms)
2021-09-10 13:19:19,767 - Уровень INFO в web_log.py.log: 127.0.0.1 [10/Sep/2021:10:19:19 +0000] "POST / HTTP/1.1" 200 158 "-" "-"
2021-09-10 13:19:29,194 - Уровень INFO в logging.py.on_pre_process_message: Received message [ID:1213] in chat [private:482930388]
2021-09-10 13:19:29,400 - Уровень INFO в logging.py.on_post_process_update: Process update [ID:88022760]: [success] (in 206 ms)
2021-09-10 13:19:29,402 - Уровень INFO в web_log.py.log: 127.0.0.1 [10/Sep/2021:10:19:29 +0000] "POST / HTTP/1.1" 200 158 "-" "-"
2021-10-16 07:42:33,979 - Уровень INFO в executor.py._welcome: Bot: CyberEvil [@cyber_evil_bot]
2021-10-16 07:42:35,529 - Уровень WARNING в executor.py._skip_updates: Updates were skipped successfully.
2021-10-16 07:42:54,593 - Уровень INFO в logging.py.on_pre_process_message: Received message [ID:1218] in chat [private:482930388]
2021-10-16 07:42:55,159 - Уровень INFO в logging.py.on_post_process_update: Process update [ID:88022766]: [success] (in 566 ms)
2021-10-16 07:42:55,169 - Уровень INFO в web_log.py.log: 127.0.0.1 [16/Oct/2021:04:42:54 +0000] "POST / HTTP/1.1" 200 159 "-" "-"
2021-10-16 07:42:57,921 - Уровень INFO в logging.py.on_pre_process_message: Received message [ID:1220] in chat [private:482930388]
2021-10-16 07:42:58,129 - Уровень INFO в logging.py.on_post_process_update: Process update [ID:88022767]: [success] (in 208 ms)
2021-10-16 07:42:58,136 - Уровень INFO в web_log.py.log: 127.0.0.1 [16/Oct/2021:04:42:57 +0000] "POST / HTTP/1.1" 200 159 "-" "-"
2021-10-16 07:42:59,745 - Уровень INFO в logging.py.on_pre_process_message: Received message [ID:1222] in chat [private:482930388]
2021-10-16 07:42:59,949 - Уровень INFO в logging.py.on_post_process_update: Process update [ID:88022768]: [success] (in 204 ms)
2021-10-16 07:42:59,953 - Уровень INFO в web_log.py.log: 127.0.0.1 [16/Oct/2021:04:42:59 +0000] "POST / HTTP/1.1" 200 159 "-" "-"
2021-10-16 07:51:04,173 - Уровень INFO в logging.py.on_pre_process_message: Received message [ID:1224] in chat [private:482930388]
2021-10-16 07:51:04,849 - Уровень INFO в logging.py.on_post_process_update: Process update [ID:88022769]: [success] (in 676 ms)
2021-10-16 07:51:04,852 - Уровень INFO в web_log.py.log: 127.0.0.1 [16/Oct/2021:04:51:04 +0000] "POST / HTTP/1.1" 200 159 "-" "-"
2021-10-16 07:51:06,674 - Уровень INFO в logging.py.on_pre_process_message: Received message [ID:1226] in chat [private:482930388]
2021-10-16 07:51:06,874 - Уровень INFO в logging.py.on_post_process_update: Process update [ID:88022770]: [success] (in 199 ms)
2021-10-16 07:51:06,874 - Уровень INFO в web_log.py.log: 127.0.0.1 [16/Oct/2021:04:51:06 +0000] "POST / HTTP/1.1" 200 159 "-" "-"
2021-10-16 07:51:09,132 - Уровень INFO в logging.py.on_pre_process_message: Received message [ID:1228] in chat [private:482930388]
2021-10-16 07:51:09,429 - Уровень INFO в logging.py.on_post_process_update: Process update [ID:88022771]: [success] (in 297 ms)
2021-10-16 07:51:09,432 - Уровень INFO в web_log.py.log: 127.0.0.1 [16/Oct/2021:04:51:09 +0000] "POST / HTTP/1.1" 200 159 "-" "-"
2021-10-16 08:03:34,978 - Уровень INFO в executor.py._welcome: Bot: CyberEvil [@cyber_evil_bot]
2021-10-16 08:03:36,704 - Уровень WARNING в executor.py._skip_updates: Updates were skipped successfully.
2021-10-16 08:04:08,853 - Уровень INFO в logging.py.on_pre_process_message: Received message [ID:1230] in chat [private:482930388]
2021-10-16 08:04:09,462 - Уровень INFO в logging.py.on_post_process_update: Process update [ID:88022772]: [success] (in 610 ms)
2021-10-16 08:04:09,463 - Уровень INFO в web_log.py.log: 127.0.0.1 [16/Oct/2021:05:04:08 +0000] "POST / HTTP/1.1" 200 159 "-" "-"
2021-10-16 08:04:10,668 - Уровень INFO в logging.py.on_pre_process_message: Received message [ID:1232] in chat [private:482930388]
2021-10-16 08:04:10,889 - Уровень INFO в logging.py.on_post_process_update: Process update [ID:88022773]: [success] (in 220 ms)
2021-10-16 08:04:10,893 - Уровень INFO в web_log.py.log: 127.0.0.1 [16/Oct/2021:05:04:10 +0000] "POST / HTTP/1.1" 200 159 "-" "-"
2021-10-16 08:04:12,497 - Уровень INFO в logging.py.on_pre_process_message: Received message [ID:1234] in chat [private:482930388]
2021-10-16 08:04:12,939 - Уровень INFO в logging.py.on_post_process_update: Process update [ID:88022774]: [success] (in 442 ms)
2021-10-16 08:04:12,947 - Уровень INFO в web_log.py.log: 127.0.0.1 [16/Oct/2021:05:04:12 +0000] "POST / HTTP/1.1" 200 159 "-" "-"
2021-10-16 08:04:56,063 - Уровень INFO в executor.py._welcome: Bot: CyberEvil [@cyber_evil_bot]
2021-10-16 08:04:57,629 - Уровень WARNING в executor.py._skip_updates: Updates were skipped successfully.
2021-10-16 08:05:05,450 - Уровень INFO в logging.py.on_pre_process_message: Received message [ID:1237] in chat [private:482930388]
2021-10-16 08:05:05,924 - Уровень INFO в logging.py.on_post_process_update: Process update [ID:88022775]: [success] (in 474 ms)
2021-10-16 08:05:05,928 - Уровень INFO в web_log.py.log: 127.0.0.1 [16/Oct/2021:05:05:05 +0000] "POST / HTTP/1.1" 200 159 "-" "-"
2021-10-16 08:05:12,086 - Уровень INFO в logging.py.on_pre_process_message: Received message [ID:1239] in chat [private:482930388]
2021-10-16 08:05:12,087 - Уровень INFO в logging.py.on_post_process_update: Process update [ID:88022776]: [success] (in 1 ms)
2021-10-16 08:05:12,087 - Уровень INFO в web_log.py.log: 127.0.0.1 [16/Oct/2021:05:05:12 +0000] "POST / HTTP/1.1" 200 159 "-" "-"
2021-10-16 08:09:38,772 - Уровень INFO в logging.py.on_pre_process_message: Received message [ID:1240] in chat [private:944922861]
2021-10-16 08:09:39,478 - Уровень INFO в logging.py.on_post_process_update: Process update [ID:88022777]: [success] (in 706 ms)
2021-10-16 08:09:39,482 - Уровень INFO в web_log.py.log: 127.0.0.1 [16/Oct/2021:05:09:38 +0000] "POST / HTTP/1.1" 200 159 "-" "-"
2021-10-16 08:10:01,643 - Уровень INFO в logging.py.on_pre_process_message: Received message [ID:1242] in chat [private:944922861]
2021-10-16 08:10:02,249 - Уровень INFO в logging.py.on_post_process_update: Process update [ID:88022778]: [success] (in 606 ms)
2021-10-16 08:10:02,253 - Уровень INFO в web_log.py.log: 127.0.0.1 [16/Oct/2021:05:10:01 +0000] "POST / HTTP/1.1" 200 159 "-" "-"
2021-10-16 08:10:03,980 - Уровень INFO в logging.py.on_pre_process_message: Received message [ID:1244] in chat [private:944922861]
2021-10-16 08:10:04,609 - Уровень INFO в logging.py.on_post_process_update: Process update [ID:88022779]: [success] (in 629 ms)
2021-10-16 08:10:04,611 - Уровень INFO в web_log.py.log: 127.0.0.1 [16/Oct/2021:05:10:03 +0000] "POST / HTTP/1.1" 200 159 "-" "-"
2021-10-16 08:10:16,970 - Уровень INFO в logging.py.on_pre_process_message: Received message [ID:1246] in chat [private:944922861]
2021-10-16 08:10:17,623 - Уровень INFO в logging.py.on_post_process_update: Process update [ID:88022780]: [success] (in 654 ms)
2021-10-16 08:10:17,627 - Уровень INFO в web_log.py.log: 127.0.0.1 [16/Oct/2021:05:10:16 +0000] "POST / HTTP/1.1" 200 159 "-" "-"
2021-10-16 08:10:31,077 - Уровень INFO в logging.py.on_pre_process_message: Received message [ID:1248] in chat [private:944922861]
2021-10-16 08:10:31,369 - Уровень INFO в logging.py.on_post_process_update: Process update [ID:88022781]: [success] (in 292 ms)
2021-10-16 08:10:31,374 - Уровень INFO в web_log.py.log: 127.0.0.1 [16/Oct/2021:05:10:31 +0000] "POST / HTTP/1.1" 200 159 "-" "-"
2021-10-16 08:10:48,141 - Уровень INFO в logging.py.on_pre_process_message: Received message [ID:1250] in chat [private:944922861]
2021-10-16 08:10:48,141 - Уровень INFO в logging.py.on_post_process_update: Process update [ID:88022782]: [success] (in 1 ms)
2021-10-16 08:10:48,142 - Уровень INFO в web_log.py.log: 127.0.0.1 [16/Oct/2021:05:10:48 +0000] "POST / HTTP/1.1" 200 159 "-" "-"
2021-10-16 08:11:10,110 - Уровень INFO в logging.py.on_pre_process_message: Received message [ID:1251] in chat [private:944922861]
2021-10-16 08:11:10,111 - Уровень INFO в logging.py.on_post_process_update: Process update [ID:88022783]: [success] (in 1 ms)
2021-10-16 08:11:10,112 - Уровень INFO в web_log.py.log: 127.0.0.1 [16/Oct/2021:05:11:10 +0000] "POST / HTTP/1.1" 200 159 "-" "-"
2021-10-16 08:11:11,872 - Уровень INFO в logging.py.on_pre_process_message: Received message [ID:1252] in chat [private:944922861]
2021-10-16 08:11:11,873 - Уровень INFO в web_log.py.log: 127.0.0.1 [16/Oct/2021:05:11:11 +0000] "POST / HTTP/1.1" 200 159 "-" "-"
2021-10-16 08:11:13,662 - Уровень INFO в logging.py.on_pre_process_message: Received message [ID:1253] in chat [private:944922861]
2021-10-16 08:11:13,663 - Уровень INFO в logging.py.on_post_process_update: Process update [ID:88022785]: [success] (in 1 ms)
2021-10-16 08:11:13,663 - Уровень INFO в web_log.py.log: 127.0.0.1 [16/Oct/2021:05:11:13 +0000] "POST / HTTP/1.1" 200 159 "-" "-"
2021-10-16 08:11:15,638 - Уровень INFO в logging.py.on_pre_process_message: Received message [ID:1254] in chat [private:944922861]
2021-10-16 08:11:15,639 - Уровень INFO в logging.py.on_post_process_update: Process update [ID:88022786]: [success] (in 1 ms)
2021-10-16 08:11:15,640 - Уровень INFO в web_log.py.log: 127.0.0.1 [16/Oct/2021:05:11:15 +0000] "POST / HTTP/1.1" 200 159 "-" "-"
2021-10-16 08:11:44,788 - Уровень INFO в executor.py._welcome: Bot: CyberEvil [@cyber_evil_bot]
2021-10-16 08:11:46,343 - Уровень WARNING в executor.py._skip_updates: Updates were skipped successfully.
2021-10-16 08:12:04,263 - Уровень INFO в logging.py.on_pre_process_message: Received message [ID:1255] in chat [private:482930388]
2021-10-16 08:12:04,918 - Уровень INFO в logging.py.on_post_process_update: Process update [ID:88022787]: [success] (in 656 ms)
2021-10-16 08:12:04,922 - Уровень INFO в web_log.py.log: 127.0.0.1 [16/Oct/2021:05:12:04 +0000] "POST / HTTP/1.1" 200 159 "-" "-"
2021-10-16 08:12:06,697 - Уровень INFO в logging.py.on_pre_process_message: Received message [ID:1257] in chat [private:482930388]
2021-10-16 08:12:06,898 - Уровень INFO в logging.py.on_post_process_update: Process update [ID:88022788]: [success] (in 201 ms)
2021-10-16 08:12:06,905 - Уровень INFO в web_log.py.log: 127.0.0.1 [16/Oct/2021:05:12:06 +0000] "POST / HTTP/1.1" 200 159 "-" "-"
2021-10-16 08:12:07,754 - Уровень INFO в logging.py.on_pre_process_message: Received message [ID:1259] in chat [private:482930388]
2021-10-16 08:12:07,969 - Уровень INFO в logging.py.on_post_process_update: Process update [ID:88022789]: [success] (in 214 ms)
2021-10-16 08:12:07,974 - Уровень INFO в web_log.py.log: 127.0.0.1 [16/Oct/2021:05:12:07 +0000] "POST / HTTP/1.1" 200 159 "-" "-"
2021-10-16 08:12:08,986 - Уровень INFO в logging.py.on_pre_process_message: Received message [ID:1261] in chat [private:482930388]
2021-10-16 08:12:09,329 - Уровень INFO в logging.py.on_post_process_update: Process update [ID:88022790]: [success] (in 342 ms)
2021-10-16 08:12:09,330 - Уровень INFO в web_log.py.log: 127.0.0.1 [16/Oct/2021:05:12:08 +0000] "POST / HTTP/1.1" 200 159 "-" "-"
2021-10-16 08:12:10,129 - Уровень INFO в logging.py.on_pre_process_message: Received message [ID:1263] in chat [private:482930388]
2021-10-16 08:12:10,439 - Уровень INFO в logging.py.on_post_process_update: Process update [ID:88022791]: [success] (in 309 ms)
2021-10-16 08:12:10,446 - Уровень INFO в web_log.py.log: 127.0.0.1 [16/Oct/2021:05:12:10 +0000] "POST / HTTP/1.1" 200 159 "-" "-"
2021-10-16 08:12:11,210 - Уровень INFO в logging.py.on_pre_process_message: Received message [ID:1265] in chat [private:482930388]
2021-10-16 08:12:11,428 - Уровень INFO в logging.py.on_post_process_update: Process update [ID:88022792]: [success] (in 218 ms)
2021-10-16 08:12:11,433 - Уровень INFO в web_log.py.log: 127.0.0.1 [16/Oct/2021:05:12:11 +0000] "POST / HTTP/1.1" 200 159 "-" "-"
2021-10-16 08:12:12,322 - Уровень INFO в logging.py.on_pre_process_message: Received message [ID:1267] in chat [private:482930388]
2021-10-16 08:12:12,522 - Уровень INFO в logging.py.on_post_process_update: Process update [ID:88022793]: [success] (in 200 ms)
2021-10-16 08:12:12,523 - Уровень INFO в web_log.py.log: 127.0.0.1 [16/Oct/2021:05:12:12 +0000] "POST / HTTP/1.1" 200 159 "-" "-"
2021-10-16 08:23:16,588 - Уровень INFO в executor.py._welcome: Bot: CyberEvil [@cyber_evil_bot]
2021-10-16 08:23:18,058 - Уровень WARNING в executor.py._skip_updates: Updates were skipped successfully.
2021-10-16 08:23:57,898 - Уровень INFO в executor.py._welcome: Bot: CyberEvil [@cyber_evil_bot]
2021-10-16 08:23:58,369 - Уровень WARNING в executor.py._skip_updates: Updates were skipped successfully.
2021-10-16 08:23:59,232 - Уровень INFO в logging.py.on_pre_process_message: Received message [ID:1271] in chat [private:482930388]
2021-10-16 08:23:59,418 - Уровень INFO в logging.py.on_post_process_update: Process update [ID:88022796]: [success] (in 186 ms)
2021-10-16 08:23:59,427 - Уровень INFO в web_log.py.log: 127.0.0.1 [16/Oct/2021:05:23:59 +0000] "POST / HTTP/1.1" 200 159 "-" "-"
2021-10-16 08:24:02,809 - Уровень INFO в logging.py.on_pre_process_message: Received message [ID:1273] in chat [private:482930388]
2021-10-16 08:24:02,998 - Уровень INFO в logging.py.on_post_process_update: Process update [ID:88022797]: [success] (in 190 ms)
2021-10-16 08:24:03,007 - Уровень INFO в web_log.py.log: 127.0.0.1 [16/Oct/2021:05:24:02 +0000] "POST / HTTP/1.1" 200 159 "-" "-"
2021-10-16 08:27:21,428 - Уровень INFO в logging.py.on_pre_process_message: Received message [ID:1275] in chat [private:816949565]
2021-10-16 08:27:21,938 - Уровень INFO в logging.py.on_post_process_update: Process update [ID:88022798]: [success] (in 510 ms)
2021-10-16 08:27:21,948 - Уровень INFO в web_log.py.log: 127.0.0.1 [16/Oct/2021:05:27:21 +0000] "POST / HTTP/1.1" 200 159 "-" "-"
2021-10-16 08:27:30,555 - Уровень INFO в logging.py.on_pre_process_message: Received message [ID:1277] in chat [private:482930388]
2021-10-16 08:27:30,758 - Уровень INFO в logging.py.on_post_process_update: Process update [ID:88022799]: [success] (in 203 ms)
2021-10-16 08:27:30,763 - Уровень INFO в web_log.py.log: 127.0.0.1 [16/Oct/2021:05:27:30 +0000] "POST / HTTP/1.1" 200 159 "-" "-"
2021-10-16 08:38:38,993 - Уровень INFO в logging.py.on_pre_process_message: Received message [ID:1279] in chat [private:482930388]
2021-10-16 08:38:39,933 - Уровень INFO в logging.py.on_post_process_update: Process update [ID:88022800]: [success] (in 940 ms)
2021-10-16 08:38:39,938 - Уровень INFO в web_log.py.log: 127.0.0.1 [16/Oct/2021:05:38:39 +0000] "POST / HTTP/1.1" 200 159 "-" "-"
2021-10-16 08:38:43,061 - Уровень INFO в logging.py.on_pre_process_message: Received message [ID:1281] in chat [private:482930388]
2021-10-16 08:38:43,379 - Уровень INFO в logging.py.on_post_process_update: Process update [ID:88022801]: [success] (in 318 ms)
2021-10-16 08:38:43,381 - Уровень INFO в web_log.py.log: 127.0.0.1 [16/Oct/2021:05:38:43 +0000] "POST / HTTP/1.1" 200 159 "-" "-"
2021-10-16 10:01:06,181 - Уровень INFO в logging.py.on_pre_process_message: Received message [ID:1283] in chat [private:944922861]
2021-10-16 10:01:06,183 - Уровень INFO в web_log.py.log: 127.0.0.1 [16/Oct/2021:07:01:06 +0000] "POST / HTTP/1.1" 200 159 "-" "-"
2021-10-16 10:01:21,143 - Уровень INFO в logging.py.on_pre_process_message: Received message [ID:1284] in chat [private:944922861]
2021-10-16 10:01:21,145 - Уровень INFO в web_log.py.log: 127.0.0.1 [16/Oct/2021:07:01:21 +0000] "POST / HTTP/1.1" 200 159 "-" "-"
2021-10-16 10:01:28,771 - Уровень INFO в logging.py.on_pre_process_message: Received message [ID:1285] in chat [private:944922861]
2021-10-16 10:01:28,772 - Уровень INFO в logging.py.on_post_process_update: Process update [ID:88022804]: [success] (in 1 ms)
2021-10-16 10:01:28,773 - Уровень INFO в web_log.py.log: 127.0.0.1 [16/Oct/2021:07:01:28 +0000] "POST / HTTP/1.1" 200 159 "-" "-"
2021-10-26 08:53:12,265 - Уровень INFO в executor.py._welcome: Bot: CyberEvil [@cyber_evil_bot]
2021-10-26 08:53:13,719 - Уровень WARNING в executor.py._skip_updates: Updates were skipped successfully.
2021-10-26 08:53:45,032 - Уровень INFO в logging.py.on_pre_process_message: Received message [ID:1287] in chat [private:482930388]
2021-10-26 08:53:45,623 - Уровень INFO в logging.py.on_post_process_update: Process update [ID:88022806]: [success] (in 591 ms)
2021-10-26 08:53:45,624 - Уровень INFO в web_log.py.log: 127.0.0.1 [26/Oct/2021:05:53:45 +0000] "POST / HTTP/1.1" 200 158 "-" "-"
2021-10-26 08:57:00,422 - Уровень WARNING в main.py.on_shutdown: Shutting down..
2021-10-26 08:57:00,885 - Уровень WARNING в main.py.on_shutdown: Bye!
2021-10-26 08:57:02,965 - Уровень INFO в executor.py._welcome: Bot: CyberEvil [@cyber_evil_bot]
2021-10-26 08:57:04,694 - Уровень WARNING в executor.py._skip_updates: Updates were skipped successfully.
2021-10-26 08:57:26,953 - Уровень INFO в logging.py.on_pre_process_message: Received message [ID:1289] in chat [private:482930388]
2021-10-26 08:57:27,545 - Уровень INFO в logging.py.on_post_process_update: Process update [ID:88022807]: [success] (in 592 ms)
2021-10-26 08:57:27,546 - Уровень INFO в web_log.py.log: 127.0.0.1 [26/Oct/2021:05:57:26 +0000] "POST / HTTP/1.1" 200 158 "-" "-"
2021-10-26 08:57:29,085 - Уровень INFO в logging.py.on_pre_process_message: Received message [ID:1291] in chat [private:482930388]
2021-10-26 08:57:29,333 - Уровень INFO в logging.py.on_post_process_update: Process update [ID:88022808]: [success] (in 248 ms)
2021-10-26 08:57:29,335 - Уровень INFO в web_log.py.log: 127.0.0.1 [26/Oct/2021:05:57:29 +0000] "POST / HTTP/1.1" 200 158 "-" "-"
2021-10-26 08:58:26,573 - Уровень WARNING в main.py.on_shutdown: Shutting down..
2021-10-26 08:58:27,013 - Уровень WARNING в main.py.on_shutdown: Bye!
2021-10-26 08:58:29,350 - Уровень INFO в executor.py._welcome: Bot: CyberEvil [@cyber_evil_bot]
2021-10-26 08:58:30,654 - Уровень WARNING в executor.py._skip_updates: Updates were skipped successfully.
2021-10-26 08:58:37,258 - Уровень INFO в logging.py.on_pre_process_message: Received message [ID:1293] in chat [private:482930388]
2021-10-26 08:58:37,442 - Уровень INFO в logging.py.on_post_process_update: Process update [ID:88022809]: [success] (in 184 ms)
2021-10-26 08:58:37,445 - Уровень INFO в web_log.py.log: 127.0.0.1 [26/Oct/2021:05:58:37 +0000] "POST / HTTP/1.1" 200 158 "-" "-"
2021-10-26 08:58:38,778 - Уровень INFO в logging.py.on_pre_process_message: Received message [ID:1295] in chat [private:482930388]
2021-10-26 08:58:38,964 - Уровень INFO в logging.py.on_post_process_update: Process update [ID:88022810]: [success] (in 186 ms)
2021-10-26 08:58:38,965 - Уровень INFO в web_log.py.log: 127.0.0.1 [26/Oct/2021:05:58:38 +0000] "POST / HTTP/1.1" 200 158 "-" "-"
2021-10-26 08:58:40,968 - Уровень INFO в logging.py.on_pre_process_message: Received message [ID:1297] in chat [private:482930388]
2021-10-26 08:58:40,970 - Уровень INFO в logging.py.on_pre_process_error: Process update [ID:88022811]: [failed] (in 3 ms)
2021-10-26 08:58:40,970 - Уровень ERROR в web_protocol.py.log_exception: Error handling request
Traceback (most recent call last):
  File "E:\Koд\bot\venv\lib\site-packages\aiohttp\web_protocol.py", line 422, in _handle_request
    resp = await self._request_handler(request)
  File "E:\Koд\bot\venv\lib\site-packages\aiohttp\web_app.py", line 499, in _handle
    resp = await handler(request)
  File "E:\Koд\bot\venv\lib\site-packages\aiohttp\web_urldispatcher.py", line 948, in _iter
    resp = await method()
  File "E:\Koд\bot\venv\lib\site-packages\aiogram\dispatcher\webhook.py", line 139, in post
    results = await self.process_update(update)
  File "E:\Koд\bot\venv\lib\site-packages\aiogram\dispatcher\webhook.py", line 190, in process_update
    return fut.result()
  File "E:\Koд\bot\venv\lib\site-packages\aiogram\dispatcher\handler.py", line 116, in notify
    response = await handler_obj.handler(*args, **partial_data)
  File "E:\Koд\bot\venv\lib\site-packages\aiogram\dispatcher\dispatcher.py", line 259, in process_update
    return await self.message_handlers.notify(update.message)
  File "E:\Koд\bot\venv\lib\site-packages\aiogram\dispatcher\handler.py", line 116, in notify
    response = await handler_obj.handler(*args, **partial_data)
  File ".\main.py", line 73, in bot_message
    await bot.send_message(message.from_user.id, reply_markup=nav.btn_inline)
AttributeError: module 'markups' has no attribute 'btn_inline'
2021-10-26 08:58:40,981 - Уровень INFO в web_log.py.log: 127.0.0.1 [26/Oct/2021:05:58:40 +0000] "POST / HTTP/1.1" 500 250 "-" "-"
2021-10-26 08:58:41,875 - Уровень INFO в logging.py.on_pre_process_message: Received message [ID:1297] in chat [private:482930388]
2021-10-26 08:58:41,876 - Уровень INFO в logging.py.on_pre_process_error: Process update [ID:88022811]: [failed] (in 1 ms)
2021-10-26 08:58:41,876 - Уровень ERROR в web_protocol.py.log_exception: Error handling request
Traceback (most recent call last):
  File "E:\Koд\bot\venv\lib\site-packages\aiohttp\web_protocol.py", line 422, in _handle_request
    resp = await self._request_handler(request)
  File "E:\Koд\bot\venv\lib\site-packages\aiohttp\web_app.py", line 499, in _handle
    resp = await handler(request)
  File "E:\Koд\bot\venv\lib\site-packages\aiohttp\web_urldispatcher.py", line 948, in _iter
    resp = await method()
  File "E:\Koд\bot\venv\lib\site-packages\aiogram\dispatcher\webhook.py", line 139, in post
    results = await self.process_update(update)
  File "E:\Koд\bot\venv\lib\site-packages\aiogram\dispatcher\webhook.py", line 190, in process_update
    return fut.result()
  File "E:\Koд\bot\venv\lib\site-packages\aiogram\dispatcher\handler.py", line 116, in notify
    response = await handler_obj.handler(*args, **partial_data)
  File "E:\Koд\bot\venv\lib\site-packages\aiogram\dispatcher\dispatcher.py", line 259, in process_update
    return await self.message_handlers.notify(update.message)
  File "E:\Koд\bot\venv\lib\site-packages\aiogram\dispatcher\handler.py", line 116, in notify
    response = await handler_obj.handler(*args, **partial_data)
  File ".\main.py", line 73, in bot_message
    await bot.send_message(message.from_user.id, reply_markup=nav.btn_inline)
AttributeError: module 'markups' has no attribute 'btn_inline'
2021-10-26 08:58:41,878 - Уровень INFO в web_log.py.log: 127.0.0.1 [26/Oct/2021:05:58:41 +0000] "POST / HTTP/1.1" 500 250 "-" "-"
2021-10-26 08:58:44,577 - Уровень INFO в logging.py.on_pre_process_message: Received message [ID:1297] in chat [private:482930388]
2021-10-26 08:58:44,578 - Уровень INFO в logging.py.on_pre_process_error: Process update [ID:88022811]: [failed] (in 1 ms)
2021-10-26 08:58:44,578 - Уровень ERROR в web_protocol.py.log_exception: Error handling request
Traceback (most recent call last):
  File "E:\Koд\bot\venv\lib\site-packages\aiohttp\web_protocol.py", line 422, in _handle_request
    resp = await self._request_handler(request)
  File "E:\Koд\bot\venv\lib\site-packages\aiohttp\web_app.py", line 499, in _handle
    resp = await handler(request)
  File "E:\Koд\bot\venv\lib\site-packages\aiohttp\web_urldispatcher.py", line 948, in _iter
    resp = await method()
  File "E:\Koд\bot\venv\lib\site-packages\aiogram\dispatcher\webhook.py", line 139, in post
    results = await self.process_update(update)
  File "E:\Koд\bot\venv\lib\site-packages\aiogram\dispatcher\webhook.py", line 190, in process_update
    return fut.result()
  File "E:\Koд\bot\venv\lib\site-packages\aiogram\dispatcher\handler.py", line 116, in notify
    response = await handler_obj.handler(*args, **partial_data)
  File "E:\Koд\bot\venv\lib\site-packages\aiogram\dispatcher\dispatcher.py", line 259, in process_update
    return await self.message_handlers.notify(update.message)
  File "E:\Koд\bot\venv\lib\site-packages\aiogram\dispatcher\handler.py", line 116, in notify
    response = await handler_obj.handler(*args, **partial_data)
  File ".\main.py", line 73, in bot_message
    await bot.send_message(message.from_user.id, reply_markup=nav.btn_inline)
AttributeError: module 'markups' has no attribute 'btn_inline'
2021-10-26 08:58:44,580 - Уровень INFO в web_log.py.log: 127.0.0.1 [26/Oct/2021:05:58:44 +0000] "POST / HTTP/1.1" 500 250 "-" "-"
2021-10-26 08:58:49,276 - Уровень INFO в logging.py.on_pre_process_message: Received message [ID:1297] in chat [private:482930388]
2021-10-26 08:58:49,277 - Уровень INFO в logging.py.on_pre_process_error: Process update [ID:88022811]: [failed] (in 1 ms)
2021-10-26 08:58:49,277 - Уровень ERROR в web_protocol.py.log_exception: Error handling request
Traceback (most recent call last):
  File "E:\Koд\bot\venv\lib\site-packages\aiohttp\web_protocol.py", line 422, in _handle_request
    resp = await self._request_handler(request)
  File "E:\Koд\bot\venv\lib\site-packages\aiohttp\web_app.py", line 499, in _handle
    resp = await handler(request)
  File "E:\Koд\bot\venv\lib\site-packages\aiohttp\web_urldispatcher.py", line 948, in _iter
    resp = await method()
  File "E:\Koд\bot\venv\lib\site-packages\aiogram\dispatcher\webhook.py", line 139, in post
    results = await self.process_update(update)
  File "E:\Koд\bot\venv\lib\site-packages\aiogram\dispatcher\webhook.py", line 190, in process_update
    return fut.result()
  File "E:\Koд\bot\venv\lib\site-packages\aiogram\dispatcher\handler.py", line 116, in notify
    response = await handler_obj.handler(*args, **partial_data)
  File "E:\Koд\bot\venv\lib\site-packages\aiogram\dispatcher\dispatcher.py", line 259, in process_update
    return await self.message_handlers.notify(update.message)
  File "E:\Koд\bot\venv\lib\site-packages\aiogram\dispatcher\handler.py", line 116, in notify
    response = await handler_obj.handler(*args, **partial_data)
  File ".\main.py", line 73, in bot_message
    await bot.send_message(message.from_user.id, reply_markup=nav.btn_inline)
AttributeError: module 'markups' has no attribute 'btn_inline'
2021-10-26 08:58:49,278 - Уровень INFO в web_log.py.log: 127.0.0.1 [26/Oct/2021:05:58:49 +0000] "POST / HTTP/1.1" 500 250 "-" "-"
2021-10-26 08:58:57,972 - Уровень INFO в logging.py.on_pre_process_message: Received message [ID:1297] in chat [private:482930388]
2021-10-26 08:58:57,974 - Уровень INFO в logging.py.on_pre_process_error: Process update [ID:88022811]: [failed] (in 2 ms)
2021-10-26 08:58:57,974 - Уровень ERROR в web_protocol.py.log_exception: Error handling request
Traceback (most recent call last):
  File "E:\Koд\bot\venv\lib\site-packages\aiohttp\web_protocol.py", line 422, in _handle_request
    resp = await self._request_handler(request)
  File "E:\Koд\bot\venv\lib\site-packages\aiohttp\web_app.py", line 499, in _handle
    resp = await handler(request)
  File "E:\Koд\bot\venv\lib\site-packages\aiohttp\web_urldispatcher.py", line 948, in _iter
    resp = await method()
  File "E:\Koд\bot\venv\lib\site-packages\aiogram\dispatcher\webhook.py", line 139, in post
    results = await self.process_update(update)
  File "E:\Koд\bot\venv\lib\site-packages\aiogram\dispatcher\webhook.py", line 190, in process_update
    return fut.result()
  File "E:\Koд\bot\venv\lib\site-packages\aiogram\dispatcher\handler.py", line 116, in notify
    response = await handler_obj.handler(*args, **partial_data)
  File "E:\Koд\bot\venv\lib\site-packages\aiogram\dispatcher\dispatcher.py", line 259, in process_update
    return await self.message_handlers.notify(update.message)
  File "E:\Koд\bot\venv\lib\site-packages\aiogram\dispatcher\handler.py", line 116, in notify
    response = await handler_obj.handler(*args, **partial_data)
  File ".\main.py", line 73, in bot_message
    await bot.send_message(message.from_user.id, reply_markup=nav.btn_inline)
AttributeError: module 'markups' has no attribute 'btn_inline'
2021-10-26 08:58:57,977 - Уровень INFO в web_log.py.log: 127.0.0.1 [26/Oct/2021:05:58:57 +0000] "POST / HTTP/1.1" 500 250 "-" "-"
2021-10-26 08:59:14,956 - Уровень INFO в logging.py.on_pre_process_message: Received message [ID:1297] in chat [private:482930388]
2021-10-26 08:59:14,958 - Уровень INFO в logging.py.on_pre_process_error: Process update [ID:88022811]: [failed] (in 2 ms)
2021-10-26 08:59:14,959 - Уровень ERROR в web_protocol.py.log_exception: Error handling request
Traceback (most recent call last):
  File "E:\Koд\bot\venv\lib\site-packages\aiohttp\web_protocol.py", line 422, in _handle_request
    resp = await self._request_handler(request)
  File "E:\Koд\bot\venv\lib\site-packages\aiohttp\web_app.py", line 499, in _handle
    resp = await handler(request)
  File "E:\Koд\bot\venv\lib\site-packages\aiohttp\web_urldispatcher.py", line 948, in _iter
    resp = await method()
  File "E:\Koд\bot\venv\lib\site-packages\aiogram\dispatcher\webhook.py", line 139, in post
    results = await self.process_update(update)
  File "E:\Koд\bot\venv\lib\site-packages\aiogram\dispatcher\webhook.py", line 190, in process_update
    return fut.result()
  File "E:\Koд\bot\venv\lib\site-packages\aiogram\dispatcher\handler.py", line 116, in notify
    response = await handler_obj.handler(*args, **partial_data)
  File "E:\Koд\bot\venv\lib\site-packages\aiogram\dispatcher\dispatcher.py", line 259, in process_update
    return await self.message_handlers.notify(update.message)
  File "E:\Koд\bot\venv\lib\site-packages\aiogram\dispatcher\handler.py", line 116, in notify
    response = await handler_obj.handler(*args, **partial_data)
  File ".\main.py", line 73, in bot_message
    await bot.send_message(message.from_user.id, reply_markup=nav.btn_inline)
AttributeError: module 'markups' has no attribute 'btn_inline'
2021-10-26 08:59:14,961 - Уровень INFO в web_log.py.log: 127.0.0.1 [26/Oct/2021:05:59:14 +0000] "POST / HTTP/1.1" 500 250 "-" "-"
2021-10-26 08:59:17,117 - Уровень WARNING в main.py.on_shutdown: Shutting down..
2021-10-26 08:59:17,569 - Уровень WARNING в main.py.on_shutdown: Bye!
2021-10-26 09:02:25,417 - Уровень INFO в executor.py._welcome: Bot: CyberEvil [@cyber_evil_bot]
2021-10-26 09:02:25,738 - Уровень WARNING в executor.py._skip_updates: Updates were skipped successfully.
2021-10-26 09:02:26,580 - Уровень INFO в logging.py.on_pre_process_message: Received message [ID:1297] in chat [private:482930388]
2021-10-26 09:02:26,794 - Уровень INFO в logging.py.on_post_process_update: Process update [ID:88022811]: [success] (in 213 ms)
2021-10-26 09:02:26,795 - Уровень INFO в web_log.py.log: 127.0.0.1 [26/Oct/2021:06:02:26 +0000] "POST / HTTP/1.1" 200 158 "-" "-"
2021-10-26 09:05:53,190 - Уровень INFO в logging.py.on_pre_process_message: Received message [ID:1299] in chat [private:1364184778]
2021-10-26 09:05:53,692 - Уровень INFO в logging.py.on_post_process_update: Process update [ID:88022812]: [success] (in 501 ms)
2021-10-26 09:05:53,693 - Уровень INFO в web_log.py.log: 127.0.0.1 [26/Oct/2021:06:05:53 +0000] "POST / HTTP/1.1" 200 158 "-" "-"
2021-10-26 09:05:57,120 - Уровень INFO в logging.py.on_pre_process_message: Received message [ID:1301] in chat [private:1364184778]
2021-10-26 09:05:57,538 - Уровень INFO в logging.py.on_post_process_update: Process update [ID:88022813]: [success] (in 419 ms)
2021-10-26 09:05:57,540 - Уровень INFO в web_log.py.log: 127.0.0.1 [26/Oct/2021:06:05:57 +0000] "POST / HTTP/1.1" 200 158 "-" "-"
2021-10-26 09:06:07,531 - Уровень INFO в logging.py.on_pre_process_message: Received message [ID:1303] in chat [private:1364184778]
2021-10-26 09:06:07,904 - Уровень INFO в logging.py.on_post_process_update: Process update [ID:88022814]: [success] (in 373 ms)
2021-10-26 09:06:07,906 - Уровень INFO в web_log.py.log: 127.0.0.1 [26/Oct/2021:06:06:07 +0000] "POST / HTTP/1.1" 200 158 "-" "-"
2021-10-26 09:06:11,786 - Уровень INFO в logging.py.on_pre_process_message: Received message [ID:1305] in chat [private:1364184778]
2021-10-26 09:06:11,982 - Уровень INFO в logging.py.on_post_process_update: Process update [ID:88022815]: [success] (in 196 ms)
2021-10-26 09:06:11,984 - Уровень INFO в web_log.py.log: 127.0.0.1 [26/Oct/2021:06:06:11 +0000] "POST / HTTP/1.1" 200 158 "-" "-"
2021-10-26 09:07:38,611 - Уровень WARNING в main.py.on_shutdown: Shutting down..
2021-10-26 09:07:39,179 - Уровень WARNING в main.py.on_shutdown: Bye!
2021-10-26 09:07:43,729 - Уровень INFO в executor.py._welcome: Bot: CyberEvil [@cyber_evil_bot]
2021-10-26 09:07:45,022 - Уровень WARNING в executor.py._skip_updates: Updates were skipped successfully.
2021-10-26 09:07:53,512 - Уровень INFO в logging.py.on_pre_process_message: Received message [ID:1307] in chat [private:482930388]
2021-10-26 09:07:53,742 - Уровень INFO в logging.py.on_post_process_update: Process update [ID:88022816]: [success] (in 230 ms)
2021-10-26 09:07:53,743 - Уровень INFO в web_log.py.log: 127.0.0.1 [26/Oct/2021:06:07:53 +0000] "POST / HTTP/1.1" 200 158 "-" "-"
2021-10-26 09:07:55,217 - Уровень INFO в logging.py.on_pre_process_message: Received message [ID:1309] in chat [private:482930388]
2021-10-26 09:07:55,421 - Уровень INFO в logging.py.on_post_process_update: Process update [ID:88022817]: [success] (in 202 ms)
2021-10-26 09:07:55,422 - Уровень INFO в web_log.py.log: 127.0.0.1 [26/Oct/2021:06:07:55 +0000] "POST / HTTP/1.1" 200 158 "-" "-"
2021-10-26 09:07:59,588 - Уровень INFO в logging.py.on_pre_process_message: Received message [ID:1311] in chat [private:482930388]
2021-10-26 09:07:59,735 - Уровень INFO в logging.py.on_pre_process_error: Process update [ID:88022818]: [failed] (in 147 ms)
2021-10-26 09:07:59,735 - Уровень ERROR в web_protocol.py.log_exception: Error handling request
Traceback (most recent call last):
  File "E:\Koд\bot\venv\lib\site-packages\aiohttp\web_protocol.py", line 422, in _handle_request
    resp = await self._request_handler(request)
  File "E:\Koд\bot\venv\lib\site-packages\aiohttp\web_app.py", line 499, in _handle
    resp = await handler(request)
  File "E:\Koд\bot\venv\lib\site-packages\aiohttp\web_urldispatcher.py", line 948, in _iter
    resp = await method()
  File "E:\Koд\bot\venv\lib\site-packages\aiogram\dispatcher\webhook.py", line 139, in post
    results = await self.process_update(update)
  File "E:\Koд\bot\venv\lib\site-packages\aiogram\dispatcher\webhook.py", line 190, in process_update
    return fut.result()
  File "E:\Koд\bot\venv\lib\site-packages\aiogram\dispatcher\handler.py", line 116, in notify
    response = await handler_obj.handler(*args, **partial_data)
  File "E:\Koд\bot\venv\lib\site-packages\aiogram\dispatcher\dispatcher.py", line 259, in process_update
    return await self.message_handlers.notify(update.message)
  File "E:\Koд\bot\venv\lib\site-packages\aiogram\dispatcher\handler.py", line 116, in notify
    response = await handler_obj.handler(*args, **partial_data)
  File ".\main.py", line 151, in bot_message
    await bot.send_message(message.from_user.id, tech_anal.get('USA_anal'))
  File "E:\Koд\bot\venv\lib\site-packages\aiogram\bot\bot.py", line 314, in send_message
    result = await self.request(api.Methods.SEND_MESSAGE, payload)
  File "E:\Koд\bot\venv\lib\site-packages\aiogram\bot\base.py", line 208, in request
    return await api.make_request(self.session, self.server, self.__token, method, data, files,
  File "E:\Koд\bot\venv\lib\site-packages\aiogram\bot\api.py", line 140, in make_request
    return check_result(method, response.content_type, response.status, await response.text())
  File "E:\Koд\bot\venv\lib\site-packages\aiogram\bot\api.py", line 115, in check_result
    exceptions.BadRequest.detect(description)
  File "E:\Koд\bot\venv\lib\site-packages\aiogram\utils\exceptions.py", line 140, in detect
    raise err(cls.text or description)
aiogram.utils.exceptions.MessageTextIsEmpty: Message text is empty
2021-10-26 09:07:59,743 - Уровень INFO в web_log.py.log: 127.0.0.1 [26/Oct/2021:06:07:59 +0000] "POST / HTTP/1.1" 500 250 "-" "-"
2021-10-26 09:08:00,637 - Уровень INFO в logging.py.on_pre_process_message: Received message [ID:1311] in chat [private:482930388]
2021-10-26 09:08:00,790 - Уровень INFO в logging.py.on_pre_process_error: Process update [ID:88022818]: [failed] (in 154 ms)
2021-10-26 09:08:00,791 - Уровень ERROR в web_protocol.py.log_exception: Error handling request
Traceback (most recent call last):
  File "E:\Koд\bot\venv\lib\site-packages\aiohttp\web_protocol.py", line 422, in _handle_request
    resp = await self._request_handler(request)
  File "E:\Koд\bot\venv\lib\site-packages\aiohttp\web_app.py", line 499, in _handle
    resp = await handler(request)
  File "E:\Koд\bot\venv\lib\site-packages\aiohttp\web_urldispatcher.py", line 948, in _iter
    resp = await method()
  File "E:\Koд\bot\venv\lib\site-packages\aiogram\dispatcher\webhook.py", line 139, in post
    results = await self.process_update(update)
  File "E:\Koд\bot\venv\lib\site-packages\aiogram\dispatcher\webhook.py", line 190, in process_update
    return fut.result()
  File "E:\Koд\bot\venv\lib\site-packages\aiogram\dispatcher\handler.py", line 116, in notify
    response = await handler_obj.handler(*args, **partial_data)
  File "E:\Koд\bot\venv\lib\site-packages\aiogram\dispatcher\dispatcher.py", line 259, in process_update
    return await self.message_handlers.notify(update.message)
  File "E:\Koд\bot\venv\lib\site-packages\aiogram\dispatcher\handler.py", line 116, in notify
    response = await handler_obj.handler(*args, **partial_data)
  File ".\main.py", line 151, in bot_message
    await bot.send_message(message.from_user.id, tech_anal.get('USA_anal'))
  File "E:\Koд\bot\venv\lib\site-packages\aiogram\bot\bot.py", line 314, in send_message
    result = await self.request(api.Methods.SEND_MESSAGE, payload)
  File "E:\Koд\bot\venv\lib\site-packages\aiogram\bot\base.py", line 208, in request
    return await api.make_request(self.session, self.server, self.__token, method, data, files,
  File "E:\Koд\bot\venv\lib\site-packages\aiogram\bot\api.py", line 140, in make_request
    return check_result(method, response.content_type, response.status, await response.text())
  File "E:\Koд\bot\venv\lib\site-packages\aiogram\bot\api.py", line 115, in check_result
    exceptions.BadRequest.detect(description)
  File "E:\Koд\bot\venv\lib\site-packages\aiogram\utils\exceptions.py", line 140, in detect
    raise err(cls.text or description)
aiogram.utils.exceptions.MessageTextIsEmpty: Message text is empty
2021-10-26 09:08:00,794 - Уровень INFO в web_log.py.log: 127.0.0.1 [26/Oct/2021:06:08:00 +0000] "POST / HTTP/1.1" 500 250 "-" "-"
2021-10-26 09:08:03,528 - Уровень INFO в logging.py.on_pre_process_message: Received message [ID:1311] in chat [private:482930388]
2021-10-26 09:08:03,675 - Уровень INFO в logging.py.on_pre_process_error: Process update [ID:88022818]: [failed] (in 147 ms)
2021-10-26 09:08:03,675 - Уровень ERROR в web_protocol.py.log_exception: Error handling request
Traceback (most recent call last):
  File "E:\Koд\bot\venv\lib\site-packages\aiohttp\web_protocol.py", line 422, in _handle_request
    resp = await self._request_handler(request)
  File "E:\Koд\bot\venv\lib\site-packages\aiohttp\web_app.py", line 499, in _handle
    resp = await handler(request)
  File "E:\Koд\bot\venv\lib\site-packages\aiohttp\web_urldispatcher.py", line 948, in _iter
    resp = await method()
  File "E:\Koд\bot\venv\lib\site-packages\aiogram\dispatcher\webhook.py", line 139, in post
    results = await self.process_update(update)
  File "E:\Koд\bot\venv\lib\site-packages\aiogram\dispatcher\webhook.py", line 190, in process_update
    return fut.result()
  File "E:\Koд\bot\venv\lib\site-packages\aiogram\dispatcher\handler.py", line 116, in notify
    response = await handler_obj.handler(*args, **partial_data)
  File "E:\Koд\bot\venv\lib\site-packages\aiogram\dispatcher\dispatcher.py", line 259, in process_update
    return await self.message_handlers.notify(update.message)
  File "E:\Koд\bot\venv\lib\site-packages\aiogram\dispatcher\handler.py", line 116, in notify
    response = await handler_obj.handler(*args, **partial_data)
  File ".\main.py", line 151, in bot_message
    await bot.send_message(message.from_user.id, tech_anal.get('USA_anal'))
  File "E:\Koд\bot\venv\lib\site-packages\aiogram\bot\bot.py", line 314, in send_message
    result = await self.request(api.Methods.SEND_MESSAGE, payload)
  File "E:\Koд\bot\venv\lib\site-packages\aiogram\bot\base.py", line 208, in request
    return await api.make_request(self.session, self.server, self.__token, method, data, files,
  File "E:\Koд\bot\venv\lib\site-packages\aiogram\bot\api.py", line 140, in make_request
    return check_result(method, response.content_type, response.status, await response.text())
  File "E:\Koд\bot\venv\lib\site-packages\aiogram\bot\api.py", line 115, in check_result
    exceptions.BadRequest.detect(description)
  File "E:\Koд\bot\venv\lib\site-packages\aiogram\utils\exceptions.py", line 140, in detect
    raise err(cls.text or description)
aiogram.utils.exceptions.MessageTextIsEmpty: Message text is empty
2021-10-26 09:08:03,676 - Уровень INFO в web_log.py.log: 127.0.0.1 [26/Oct/2021:06:08:03 +0000] "POST / HTTP/1.1" 500 250 "-" "-"
2021-10-26 09:08:08,372 - Уровень INFO в logging.py.on_pre_process_message: Received message [ID:1311] in chat [private:482930388]
2021-10-26 09:08:08,520 - Уровень INFO в logging.py.on_pre_process_error: Process update [ID:88022818]: [failed] (in 149 ms)
2021-10-26 09:08:08,520 - Уровень ERROR в web_protocol.py.log_exception: Error handling request
Traceback (most recent call last):
  File "E:\Koд\bot\venv\lib\site-packages\aiohttp\web_protocol.py", line 422, in _handle_request
    resp = await self._request_handler(request)
  File "E:\Koд\bot\venv\lib\site-packages\aiohttp\web_app.py", line 499, in _handle
    resp = await handler(request)
  File "E:\Koд\bot\venv\lib\site-packages\aiohttp\web_urldispatcher.py", line 948, in _iter
    resp = await method()
  File "E:\Koд\bot\venv\lib\site-packages\aiogram\dispatcher\webhook.py", line 139, in post
    results = await self.process_update(update)
  File "E:\Koд\bot\venv\lib\site-packages\aiogram\dispatcher\webhook.py", line 190, in process_update
    return fut.result()
  File "E:\Koд\bot\venv\lib\site-packages\aiogram\dispatcher\handler.py", line 116, in notify
    response = await handler_obj.handler(*args, **partial_data)
  File "E:\Koд\bot\venv\lib\site-packages\aiogram\dispatcher\dispatcher.py", line 259, in process_update
    return await self.message_handlers.notify(update.message)
  File "E:\Koд\bot\venv\lib\site-packages\aiogram\dispatcher\handler.py", line 116, in notify
    response = await handler_obj.handler(*args, **partial_data)
  File ".\main.py", line 151, in bot_message
    await bot.send_message(message.from_user.id, tech_anal.get('USA_anal'))
  File "E:\Koд\bot\venv\lib\site-packages\aiogram\bot\bot.py", line 314, in send_message
    result = await self.request(api.Methods.SEND_MESSAGE, payload)
  File "E:\Koд\bot\venv\lib\site-packages\aiogram\bot\base.py", line 208, in request
    return await api.make_request(self.session, self.server, self.__token, method, data, files,
  File "E:\Koд\bot\venv\lib\site-packages\aiogram\bot\api.py", line 140, in make_request
    return check_result(method, response.content_type, response.status, await response.text())
  File "E:\Koд\bot\venv\lib\site-packages\aiogram\bot\api.py", line 115, in check_result
    exceptions.BadRequest.detect(description)
  File "E:\Koд\bot\venv\lib\site-packages\aiogram\utils\exceptions.py", line 140, in detect
    raise err(cls.text or description)
aiogram.utils.exceptions.MessageTextIsEmpty: Message text is empty
2021-10-26 09:08:08,524 - Уровень INFO в web_log.py.log: 127.0.0.1 [26/Oct/2021:06:08:08 +0000] "POST / HTTP/1.1" 500 250 "-" "-"
2021-10-26 09:08:17,218 - Уровень INFO в logging.py.on_pre_process_message: Received message [ID:1311] in chat [private:482930388]
2021-10-26 09:08:17,367 - Уровень INFO в logging.py.on_pre_process_error: Process update [ID:88022818]: [failed] (in 150 ms)
2021-10-26 09:08:17,368 - Уровень ERROR в web_protocol.py.log_exception: Error handling request
Traceback (most recent call last):
  File "E:\Koд\bot\venv\lib\site-packages\aiohttp\web_protocol.py", line 422, in _handle_request
    resp = await self._request_handler(request)
  File "E:\Koд\bot\venv\lib\site-packages\aiohttp\web_app.py", line 499, in _handle
    resp = await handler(request)
  File "E:\Koд\bot\venv\lib\site-packages\aiohttp\web_urldispatcher.py", line 948, in _iter
    resp = await method()
  File "E:\Koд\bot\venv\lib\site-packages\aiogram\dispatcher\webhook.py", line 139, in post
    results = await self.process_update(update)
  File "E:\Koд\bot\venv\lib\site-packages\aiogram\dispatcher\webhook.py", line 190, in process_update
    return fut.result()
  File "E:\Koд\bot\venv\lib\site-packages\aiogram\dispatcher\handler.py", line 116, in notify
    response = await handler_obj.handler(*args, **partial_data)
  File "E:\Koд\bot\venv\lib\site-packages\aiogram\dispatcher\dispatcher.py", line 259, in process_update
    return await self.message_handlers.notify(update.message)
  File "E:\Koд\bot\venv\lib\site-packages\aiogram\dispatcher\handler.py", line 116, in notify
    response = await handler_obj.handler(*args, **partial_data)
  File ".\main.py", line 151, in bot_message
    await bot.send_message(message.from_user.id, tech_anal.get('USA_anal'))
  File "E:\Koд\bot\venv\lib\site-packages\aiogram\bot\bot.py", line 314, in send_message
    result = await self.request(api.Methods.SEND_MESSAGE, payload)
  File "E:\Koд\bot\venv\lib\site-packages\aiogram\bot\base.py", line 208, in request
    return await api.make_request(self.session, self.server, self.__token, method, data, files,
  File "E:\Koд\bot\venv\lib\site-packages\aiogram\bot\api.py", line 140, in make_request
    return check_result(method, response.content_type, response.status, await response.text())
  File "E:\Koд\bot\venv\lib\site-packages\aiogram\bot\api.py", line 115, in check_result
    exceptions.BadRequest.detect(description)
  File "E:\Koд\bot\venv\lib\site-packages\aiogram\utils\exceptions.py", line 140, in detect
    raise err(cls.text or description)
aiogram.utils.exceptions.MessageTextIsEmpty: Message text is empty
2021-10-26 09:08:17,372 - Уровень INFO в web_log.py.log: 127.0.0.1 [26/Oct/2021:06:08:17 +0000] "POST / HTTP/1.1" 500 250 "-" "-"
2021-10-26 09:08:20,323 - Уровень INFO в logging.py.on_pre_process_message: Received message [ID:1313] in chat [private:1364184778]
2021-10-26 09:08:20,524 - Уровень INFO в logging.py.on_post_process_update: Process update [ID:88022820]: [success] (in 202 ms)
2021-10-26 09:08:20,526 - Уровень INFO в web_log.py.log: 127.0.0.1 [26/Oct/2021:06:08:20 +0000] "POST / HTTP/1.1" 200 158 "-" "-"
2021-10-26 09:08:21,807 - Уровень WARNING в main.py.on_shutdown: Shutting down..
2021-10-26 09:08:21,951 - Уровень WARNING в main.py.on_shutdown: Bye!
2021-10-26 09:08:23,975 - Уровень INFO в executor.py._welcome: Bot: CyberEvil [@cyber_evil_bot]
2021-10-26 09:08:25,285 - Уровень WARNING в executor.py._skip_updates: Updates were skipped successfully.
2021-10-26 09:08:54,152 - Уровень WARNING в main.py.on_shutdown: Shutting down..
2021-10-26 09:08:54,612 - Уровень WARNING в main.py.on_shutdown: Bye!
2021-10-26 09:08:56,352 - Уровень INFO в executor.py._welcome: Bot: CyberEvil [@cyber_evil_bot]
2021-10-26 09:08:57,685 - Уровень WARNING в executor.py._skip_updates: Updates were skipped successfully.
2021-10-26 09:08:59,948 - Уровень INFO в logging.py.on_pre_process_message: Received message [ID:1315] in chat [private:482930388]
2021-10-26 09:09:00,093 - Уровень INFO в logging.py.on_pre_process_error: Process update [ID:88022821]: [failed] (in 145 ms)
2021-10-26 09:09:00,093 - Уровень ERROR в web_protocol.py.log_exception: Error handling request
Traceback (most recent call last):
  File "E:\Koд\bot\venv\lib\site-packages\aiohttp\web_protocol.py", line 422, in _handle_request
    resp = await self._request_handler(request)
  File "E:\Koд\bot\venv\lib\site-packages\aiohttp\web_app.py", line 499, in _handle
    resp = await handler(request)
  File "E:\Koд\bot\venv\lib\site-packages\aiohttp\web_urldispatcher.py", line 948, in _iter
    resp = await method()
  File "E:\Koд\bot\venv\lib\site-packages\aiogram\dispatcher\webhook.py", line 139, in post
    results = await self.process_update(update)
  File "E:\Koд\bot\venv\lib\site-packages\aiogram\dispatcher\webhook.py", line 190, in process_update
    return fut.result()
  File "E:\Koд\bot\venv\lib\site-packages\aiogram\dispatcher\handler.py", line 116, in notify
    response = await handler_obj.handler(*args, **partial_data)
  File "E:\Koд\bot\venv\lib\site-packages\aiogram\dispatcher\dispatcher.py", line 259, in process_update
    return await self.message_handlers.notify(update.message)
  File "E:\Koд\bot\venv\lib\site-packages\aiogram\dispatcher\handler.py", line 116, in notify
    response = await handler_obj.handler(*args, **partial_data)
  File ".\main.py", line 149, in bot_message
    await bot.send_message(message.from_user.id, tech_anal.get('RU_anal'))
  File "E:\Koд\bot\venv\lib\site-packages\aiogram\bot\bot.py", line 314, in send_message
    result = await self.request(api.Methods.SEND_MESSAGE, payload)
  File "E:\Koд\bot\venv\lib\site-packages\aiogram\bot\base.py", line 208, in request
    return await api.make_request(self.session, self.server, self.__token, method, data, files,
  File "E:\Koд\bot\venv\lib\site-packages\aiogram\bot\api.py", line 140, in make_request
    return check_result(method, response.content_type, response.status, await response.text())
  File "E:\Koд\bot\venv\lib\site-packages\aiogram\bot\api.py", line 115, in check_result
    exceptions.BadRequest.detect(description)
  File "E:\Koд\bot\venv\lib\site-packages\aiogram\utils\exceptions.py", line 140, in detect
    raise err(cls.text or description)
aiogram.utils.exceptions.MessageTextIsEmpty: Message text is empty
2021-10-26 09:09:00,108 - Уровень INFO в web_log.py.log: 127.0.0.1 [26/Oct/2021:06:08:59 +0000] "POST / HTTP/1.1" 500 250 "-" "-"
2021-10-26 09:09:00,987 - Уровень INFO в logging.py.on_pre_process_message: Received message [ID:1315] in chat [private:482930388]
2021-10-26 09:09:01,128 - Уровень INFO в logging.py.on_pre_process_error: Process update [ID:88022821]: [failed] (in 142 ms)
2021-10-26 09:09:01,129 - Уровень ERROR в web_protocol.py.log_exception: Error handling request
Traceback (most recent call last):
  File "E:\Koд\bot\venv\lib\site-packages\aiohttp\web_protocol.py", line 422, in _handle_request
    resp = await self._request_handler(request)
  File "E:\Koд\bot\venv\lib\site-packages\aiohttp\web_app.py", line 499, in _handle
    resp = await handler(request)
  File "E:\Koд\bot\venv\lib\site-packages\aiohttp\web_urldispatcher.py", line 948, in _iter
    resp = await method()
  File "E:\Koд\bot\venv\lib\site-packages\aiogram\dispatcher\webhook.py", line 139, in post
    results = await self.process_update(update)
  File "E:\Koд\bot\venv\lib\site-packages\aiogram\dispatcher\webhook.py", line 190, in process_update
    return fut.result()
  File "E:\Koд\bot\venv\lib\site-packages\aiogram\dispatcher\handler.py", line 116, in notify
    response = await handler_obj.handler(*args, **partial_data)
  File "E:\Koд\bot\venv\lib\site-packages\aiogram\dispatcher\dispatcher.py", line 259, in process_update
    return await self.message_handlers.notify(update.message)
  File "E:\Koд\bot\venv\lib\site-packages\aiogram\dispatcher\handler.py", line 116, in notify
    response = await handler_obj.handler(*args, **partial_data)
  File ".\main.py", line 149, in bot_message
    await bot.send_message(message.from_user.id, tech_anal.get('RU_anal'))
  File "E:\Koд\bot\venv\lib\site-packages\aiogram\bot\bot.py", line 314, in send_message
    result = await self.request(api.Methods.SEND_MESSAGE, payload)
  File "E:\Koд\bot\venv\lib\site-packages\aiogram\bot\base.py", line 208, in request
    return await api.make_request(self.session, self.server, self.__token, method, data, files,
  File "E:\Koд\bot\venv\lib\site-packages\aiogram\bot\api.py", line 140, in make_request
    return check_result(method, response.content_type, response.status, await response.text())
  File "E:\Koд\bot\venv\lib\site-packages\aiogram\bot\api.py", line 115, in check_result
    exceptions.BadRequest.detect(description)
  File "E:\Koд\bot\venv\lib\site-packages\aiogram\utils\exceptions.py", line 140, in detect
    raise err(cls.text or description)
aiogram.utils.exceptions.MessageTextIsEmpty: Message text is empty
2021-10-26 09:09:01,131 - Уровень INFO в web_log.py.log: 127.0.0.1 [26/Oct/2021:06:09:00 +0000] "POST / HTTP/1.1" 500 250 "-" "-"
2021-10-26 09:09:03,822 - Уровень INFO в logging.py.on_pre_process_message: Received message [ID:1315] in chat [private:482930388]
2021-10-26 09:09:03,968 - Уровень INFO в logging.py.on_pre_process_error: Process update [ID:88022821]: [failed] (in 147 ms)
2021-10-26 09:09:03,968 - Уровень ERROR в web_protocol.py.log_exception: Error handling request
Traceback (most recent call last):
  File "E:\Koд\bot\venv\lib\site-packages\aiohttp\web_protocol.py", line 422, in _handle_request
    resp = await self._request_handler(request)
  File "E:\Koд\bot\venv\lib\site-packages\aiohttp\web_app.py", line 499, in _handle
    resp = await handler(request)
  File "E:\Koд\bot\venv\lib\site-packages\aiohttp\web_urldispatcher.py", line 948, in _iter
    resp = await method()
  File "E:\Koд\bot\venv\lib\site-packages\aiogram\dispatcher\webhook.py", line 139, in post
    results = await self.process_update(update)
  File "E:\Koд\bot\venv\lib\site-packages\aiogram\dispatcher\webhook.py", line 190, in process_update
    return fut.result()
  File "E:\Koд\bot\venv\lib\site-packages\aiogram\dispatcher\handler.py", line 116, in notify
    response = await handler_obj.handler(*args, **partial_data)
  File "E:\Koд\bot\venv\lib\site-packages\aiogram\dispatcher\dispatcher.py", line 259, in process_update
    return await self.message_handlers.notify(update.message)
  File "E:\Koд\bot\venv\lib\site-packages\aiogram\dispatcher\handler.py", line 116, in notify
    response = await handler_obj.handler(*args, **partial_data)
  File ".\main.py", line 149, in bot_message
    await bot.send_message(message.from_user.id, tech_anal.get('RU_anal'))
  File "E:\Koд\bot\venv\lib\site-packages\aiogram\bot\bot.py", line 314, in send_message
    result = await self.request(api.Methods.SEND_MESSAGE, payload)
  File "E:\Koд\bot\venv\lib\site-packages\aiogram\bot\base.py", line 208, in request
    return await api.make_request(self.session, self.server, self.__token, method, data, files,
  File "E:\Koд\bot\venv\lib\site-packages\aiogram\bot\api.py", line 140, in make_request
    return check_result(method, response.content_type, response.status, await response.text())
  File "E:\Koд\bot\venv\lib\site-packages\aiogram\bot\api.py", line 115, in check_result
    exceptions.BadRequest.detect(description)
  File "E:\Koд\bot\venv\lib\site-packages\aiogram\utils\exceptions.py", line 140, in detect
    raise err(cls.text or description)
aiogram.utils.exceptions.MessageTextIsEmpty: Message text is empty
2021-10-26 09:09:03,972 - Уровень INFO в web_log.py.log: 127.0.0.1 [26/Oct/2021:06:09:03 +0000] "POST / HTTP/1.1" 500 250 "-" "-"
2021-10-26 09:09:08,663 - Уровень INFO в logging.py.on_pre_process_message: Received message [ID:1315] in chat [private:482930388]
2021-10-26 09:09:08,804 - Уровень INFO в logging.py.on_pre_process_error: Process update [ID:88022821]: [failed] (in 141 ms)
2021-10-26 09:09:08,805 - Уровень ERROR в web_protocol.py.log_exception: Error handling request
Traceback (most recent call last):
  File "E:\Koд\bot\venv\lib\site-packages\aiohttp\web_protocol.py", line 422, in _handle_request
    resp = await self._request_handler(request)
  File "E:\Koд\bot\venv\lib\site-packages\aiohttp\web_app.py", line 499, in _handle
    resp = await handler(request)
  File "E:\Koд\bot\venv\lib\site-packages\aiohttp\web_urldispatcher.py", line 948, in _iter
    resp = await method()
  File "E:\Koд\bot\venv\lib\site-packages\aiogram\dispatcher\webhook.py", line 139, in post
    results = await self.process_update(update)
  File "E:\Koд\bot\venv\lib\site-packages\aiogram\dispatcher\webhook.py", line 190, in process_update
    return fut.result()
  File "E:\Koд\bot\venv\lib\site-packages\aiogram\dispatcher\handler.py", line 116, in notify
    response = await handler_obj.handler(*args, **partial_data)
  File "E:\Koд\bot\venv\lib\site-packages\aiogram\dispatcher\dispatcher.py", line 259, in process_update
    return await self.message_handlers.notify(update.message)
  File "E:\Koд\bot\venv\lib\site-packages\aiogram\dispatcher\handler.py", line 116, in notify
    response = await handler_obj.handler(*args, **partial_data)
  File ".\main.py", line 149, in bot_message
    await bot.send_message(message.from_user.id, tech_anal.get('RU_anal'))
  File "E:\Koд\bot\venv\lib\site-packages\aiogram\bot\bot.py", line 314, in send_message
    result = await self.request(api.Methods.SEND_MESSAGE, payload)
  File "E:\Koд\bot\venv\lib\site-packages\aiogram\bot\base.py", line 208, in request
    return await api.make_request(self.session, self.server, self.__token, method, data, files,
  File "E:\Koд\bot\venv\lib\site-packages\aiogram\bot\api.py", line 140, in make_request
    return check_result(method, response.content_type, response.status, await response.text())
  File "E:\Koд\bot\venv\lib\site-packages\aiogram\bot\api.py", line 115, in check_result
    exceptions.BadRequest.detect(description)
  File "E:\Koд\bot\venv\lib\site-packages\aiogram\utils\exceptions.py", line 140, in detect
    raise err(cls.text or description)
aiogram.utils.exceptions.MessageTextIsEmpty: Message text is empty
2021-10-26 09:09:08,807 - Уровень INFO в web_log.py.log: 127.0.0.1 [26/Oct/2021:06:09:08 +0000] "POST / HTTP/1.1" 500 250 "-" "-"
2021-10-26 09:09:17,502 - Уровень INFO в logging.py.on_pre_process_message: Received message [ID:1315] in chat [private:482930388]
2021-10-26 09:09:17,648 - Уровень INFO в logging.py.on_pre_process_error: Process update [ID:88022821]: [failed] (in 147 ms)
2021-10-26 09:09:17,648 - Уровень ERROR в web_protocol.py.log_exception: Error handling request
Traceback (most recent call last):
  File "E:\Koд\bot\venv\lib\site-packages\aiohttp\web_protocol.py", line 422, in _handle_request
    resp = await self._request_handler(request)
  File "E:\Koд\bot\venv\lib\site-packages\aiohttp\web_app.py", line 499, in _handle
    resp = await handler(request)
  File "E:\Koд\bot\venv\lib\site-packages\aiohttp\web_urldispatcher.py", line 948, in _iter
    resp = await method()
  File "E:\Koд\bot\venv\lib\site-packages\aiogram\dispatcher\webhook.py", line 139, in post
    results = await self.process_update(update)
  File "E:\Koд\bot\venv\lib\site-packages\aiogram\dispatcher\webhook.py", line 190, in process_update
    return fut.result()
  File "E:\Koд\bot\venv\lib\site-packages\aiogram\dispatcher\handler.py", line 116, in notify
    response = await handler_obj.handler(*args, **partial_data)
  File "E:\Koд\bot\venv\lib\site-packages\aiogram\dispatcher\dispatcher.py", line 259, in process_update
    return await self.message_handlers.notify(update.message)
  File "E:\Koд\bot\venv\lib\site-packages\aiogram\dispatcher\handler.py", line 116, in notify
    response = await handler_obj.handler(*args, **partial_data)
  File ".\main.py", line 149, in bot_message
    await bot.send_message(message.from_user.id, tech_anal.get('RU_anal'))
  File "E:\Koд\bot\venv\lib\site-packages\aiogram\bot\bot.py", line 314, in send_message
    result = await self.request(api.Methods.SEND_MESSAGE, payload)
  File "E:\Koд\bot\venv\lib\site-packages\aiogram\bot\base.py", line 208, in request
    return await api.make_request(self.session, self.server, self.__token, method, data, files,
  File "E:\Koд\bot\venv\lib\site-packages\aiogram\bot\api.py", line 140, in make_request
    return check_result(method, response.content_type, response.status, await response.text())
  File "E:\Koд\bot\venv\lib\site-packages\aiogram\bot\api.py", line 115, in check_result
    exceptions.BadRequest.detect(description)
  File "E:\Koд\bot\venv\lib\site-packages\aiogram\utils\exceptions.py", line 140, in detect
    raise err(cls.text or description)
aiogram.utils.exceptions.MessageTextIsEmpty: Message text is empty
2021-10-26 09:09:17,651 - Уровень INFO в web_log.py.log: 127.0.0.1 [26/Oct/2021:06:09:17 +0000] "POST / HTTP/1.1" 500 250 "-" "-"
2021-10-26 09:09:34,337 - Уровень INFO в logging.py.on_pre_process_message: Received message [ID:1315] in chat [private:482930388]
2021-10-26 09:09:34,763 - Уровень INFO в logging.py.on_pre_process_error: Process update [ID:88022821]: [failed] (in 427 ms)
2021-10-26 09:09:34,765 - Уровень ERROR в web_protocol.py.log_exception: Error handling request
Traceback (most recent call last):
  File "E:\Koд\bot\venv\lib\site-packages\aiohttp\web_protocol.py", line 422, in _handle_request
    resp = await self._request_handler(request)
  File "E:\Koд\bot\venv\lib\site-packages\aiohttp\web_app.py", line 499, in _handle
    resp = await handler(request)
  File "E:\Koд\bot\venv\lib\site-packages\aiohttp\web_urldispatcher.py", line 948, in _iter
    resp = await method()
  File "E:\Koд\bot\venv\lib\site-packages\aiogram\dispatcher\webhook.py", line 139, in post
    results = await self.process_update(update)
  File "E:\Koд\bot\venv\lib\site-packages\aiogram\dispatcher\webhook.py", line 190, in process_update
    return fut.result()
  File "E:\Koд\bot\venv\lib\site-packages\aiogram\dispatcher\handler.py", line 116, in notify
    response = await handler_obj.handler(*args, **partial_data)
  File "E:\Koд\bot\venv\lib\site-packages\aiogram\dispatcher\dispatcher.py", line 259, in process_update
    return await self.message_handlers.notify(update.message)
  File "E:\Koд\bot\venv\lib\site-packages\aiogram\dispatcher\handler.py", line 116, in notify
    response = await handler_obj.handler(*args, **partial_data)
  File ".\main.py", line 149, in bot_message
    await bot.send_message(message.from_user.id, tech_anal.get('RU_anal'))
  File "E:\Koд\bot\venv\lib\site-packages\aiogram\bot\bot.py", line 314, in send_message
    result = await self.request(api.Methods.SEND_MESSAGE, payload)
  File "E:\Koд\bot\venv\lib\site-packages\aiogram\bot\base.py", line 208, in request
    return await api.make_request(self.session, self.server, self.__token, method, data, files,
  File "E:\Koд\bot\venv\lib\site-packages\aiogram\bot\api.py", line 140, in make_request
    return check_result(method, response.content_type, response.status, await response.text())
  File "E:\Koд\bot\venv\lib\site-packages\aiogram\bot\api.py", line 115, in check_result
    exceptions.BadRequest.detect(description)
  File "E:\Koд\bot\venv\lib\site-packages\aiogram\utils\exceptions.py", line 140, in detect
    raise err(cls.text or description)
aiogram.utils.exceptions.MessageTextIsEmpty: Message text is empty
2021-10-26 09:09:34,766 - Уровень INFO в web_log.py.log: 127.0.0.1 [26/Oct/2021:06:09:34 +0000] "POST / HTTP/1.1" 500 250 "-" "-"
2021-10-26 09:10:05,057 - Уровень WARNING в main.py.on_shutdown: Shutting down..
2021-10-26 09:10:05,552 - Уровень WARNING в main.py.on_shutdown: Bye!
2021-10-26 09:10:07,603 - Уровень INFO в executor.py._welcome: Bot: CyberEvil [@cyber_evil_bot]
2021-10-26 09:10:07,945 - Уровень WARNING в executor.py._skip_updates: Updates were skipped successfully.
2021-10-26 09:10:08,812 - Уровень INFO в logging.py.on_pre_process_message: Received message [ID:1316] in chat [private:482930388]
2021-10-26 09:10:09,109 - Уровень INFO в logging.py.on_post_process_update: Process update [ID:88022822]: [success] (in 296 ms)
2021-10-26 09:10:09,110 - Уровень INFO в web_log.py.log: 127.0.0.1 [26/Oct/2021:06:10:08 +0000] "POST / HTTP/1.1" 200 158 "-" "-"
2021-10-26 09:10:14,029 - Уровень INFO в logging.py.on_pre_process_message: Received message [ID:1318] in chat [private:482930388]
2021-10-26 09:10:14,376 - Уровень INFO в logging.py.on_post_process_update: Process update [ID:88022823]: [success] (in 348 ms)
2021-10-26 09:10:14,377 - Уровень INFO в web_log.py.log: 127.0.0.1 [26/Oct/2021:06:10:14 +0000] "POST / HTTP/1.1" 200 158 "-" "-"
2021-10-26 09:11:51,060 - Уровень INFO в logging.py.on_pre_process_message: Received message [ID:1320] in chat [private:1364184778]
2021-10-26 09:11:51,061 - Уровень INFO в logging.py.on_post_process_update: Process update [ID:88022824]: [success] (in 2 ms)
2021-10-26 09:11:51,063 - Уровень INFO в web_log.py.log: 127.0.0.1 [26/Oct/2021:06:11:51 +0000] "POST / HTTP/1.1" 200 158 "-" "-"
2021-10-26 09:12:33,173 - Уровень INFO в logging.py.on_pre_process_message: Received message [ID:1321] in chat [private:1364184778]
2021-10-26 09:12:33,175 - Уровень INFO в logging.py.on_post_process_update: Process update [ID:88022825]: [success] (in 2 ms)
2021-10-26 09:12:33,176 - Уровень INFO в web_log.py.log: 127.0.0.1 [26/Oct/2021:06:12:33 +0000] "POST / HTTP/1.1" 200 158 "-" "-"
2021-10-26 09:40:08,657 - Уровень WARNING в main.py.on_shutdown: Shutting down..
2021-10-26 09:40:09,109 - Уровень WARNING в main.py.on_shutdown: Bye!
2021-10-26 09:40:11,723 - Уровень INFO в executor.py._welcome: Bot: CyberEvil [@cyber_evil_bot]
2021-10-26 09:40:13,017 - Уровень WARNING в executor.py._skip_updates: Updates were skipped successfully.
2021-10-26 09:40:50,063 - Уровень INFO в logging.py.on_pre_process_message: Received message [ID:1322] in chat [private:482930388]
2021-10-26 09:40:50,494 - Уровень INFO в logging.py.on_pre_process_error: Process update [ID:88022826]: [failed] (in 432 ms)
2021-10-26 09:40:50,494 - Уровень ERROR в web_protocol.py.log_exception: Error handling request
Traceback (most recent call last):
  File "E:\Koд\bot\venv\lib\site-packages\aiohttp\web_protocol.py", line 422, in _handle_request
    resp = await self._request_handler(request)
  File "E:\Koд\bot\venv\lib\site-packages\aiohttp\web_app.py", line 499, in _handle
    resp = await handler(request)
  File "E:\Koд\bot\venv\lib\site-packages\aiohttp\web_urldispatcher.py", line 948, in _iter
    resp = await method()
  File "E:\Koд\bot\venv\lib\site-packages\aiogram\dispatcher\webhook.py", line 139, in post
    results = await self.process_update(update)
  File "E:\Koд\bot\venv\lib\site-packages\aiogram\dispatcher\webhook.py", line 190, in process_update
    return fut.result()
  File "E:\Koд\bot\venv\lib\site-packages\aiogram\dispatcher\handler.py", line 116, in notify
    response = await handler_obj.handler(*args, **partial_data)
  File "E:\Koд\bot\venv\lib\site-packages\aiogram\dispatcher\dispatcher.py", line 259, in process_update
    return await self.message_handlers.notify(update.message)
  File "E:\Koд\bot\venv\lib\site-packages\aiogram\dispatcher\handler.py", line 116, in notify
    response = await handler_obj.handler(*args, **partial_data)
  File ".\main.py", line 178, in bot_message
    await bot.send_message(message.from_user.id, tech_anal.get('RU_anal'))
  File "E:\Koд\bot\venv\lib\site-packages\aiogram\bot\bot.py", line 314, in send_message
    result = await self.request(api.Methods.SEND_MESSAGE, payload)
  File "E:\Koд\bot\venv\lib\site-packages\aiogram\bot\base.py", line 208, in request
    return await api.make_request(self.session, self.server, self.__token, method, data, files,
  File "E:\Koд\bot\venv\lib\site-packages\aiogram\bot\api.py", line 140, in make_request
    return check_result(method, response.content_type, response.status, await response.text())
  File "E:\Koд\bot\venv\lib\site-packages\aiogram\bot\api.py", line 115, in check_result
    exceptions.BadRequest.detect(description)
  File "E:\Koд\bot\venv\lib\site-packages\aiogram\utils\exceptions.py", line 140, in detect
    raise err(cls.text or description)
aiogram.utils.exceptions.MessageIsTooLong: Message is too long
2021-10-26 09:40:50,510 - Уровень INFO в web_log.py.log: 127.0.0.1 [26/Oct/2021:06:40:50 +0000] "POST / HTTP/1.1" 500 250 "-" "-"
2021-10-26 09:40:51,415 - Уровень INFO в logging.py.on_pre_process_message: Received message [ID:1322] in chat [private:482930388]
2021-10-26 09:40:51,568 - Уровень INFO в logging.py.on_pre_process_error: Process update [ID:88022826]: [failed] (in 153 ms)
2021-10-26 09:40:51,569 - Уровень ERROR в web_protocol.py.log_exception: Error handling request
Traceback (most recent call last):
  File "E:\Koд\bot\venv\lib\site-packages\aiohttp\web_protocol.py", line 422, in _handle_request
    resp = await self._request_handler(request)
  File "E:\Koд\bot\venv\lib\site-packages\aiohttp\web_app.py", line 499, in _handle
    resp = await handler(request)
  File "E:\Koд\bot\venv\lib\site-packages\aiohttp\web_urldispatcher.py", line 948, in _iter
    resp = await method()
  File "E:\Koд\bot\venv\lib\site-packages\aiogram\dispatcher\webhook.py", line 139, in post
    results = await self.process_update(update)
  File "E:\Koд\bot\venv\lib\site-packages\aiogram\dispatcher\webhook.py", line 190, in process_update
    return fut.result()
  File "E:\Koд\bot\venv\lib\site-packages\aiogram\dispatcher\handler.py", line 116, in notify
    response = await handler_obj.handler(*args, **partial_data)
  File "E:\Koд\bot\venv\lib\site-packages\aiogram\dispatcher\dispatcher.py", line 259, in process_update
    return await self.message_handlers.notify(update.message)
  File "E:\Koд\bot\venv\lib\site-packages\aiogram\dispatcher\handler.py", line 116, in notify
    response = await handler_obj.handler(*args, **partial_data)
  File ".\main.py", line 178, in bot_message
    await bot.send_message(message.from_user.id, tech_anal.get('RU_anal'))
  File "E:\Koд\bot\venv\lib\site-packages\aiogram\bot\bot.py", line 314, in send_message
    result = await self.request(api.Methods.SEND_MESSAGE, payload)
  File "E:\Koд\bot\venv\lib\site-packages\aiogram\bot\base.py", line 208, in request
    return await api.make_request(self.session, self.server, self.__token, method, data, files,
  File "E:\Koд\bot\venv\lib\site-packages\aiogram\bot\api.py", line 140, in make_request
    return check_result(method, response.content_type, response.status, await response.text())
  File "E:\Koд\bot\venv\lib\site-packages\aiogram\bot\api.py", line 115, in check_result
    exceptions.BadRequest.detect(description)
  File "E:\Koд\bot\venv\lib\site-packages\aiogram\utils\exceptions.py", line 140, in detect
    raise err(cls.text or description)
aiogram.utils.exceptions.MessageIsTooLong: Message is too long
2021-10-26 09:40:51,572 - Уровень INFO в web_log.py.log: 127.0.0.1 [26/Oct/2021:06:40:51 +0000] "POST / HTTP/1.1" 500 250 "-" "-"
2021-10-26 09:40:54,271 - Уровень INFO в logging.py.on_pre_process_message: Received message [ID:1322] in chat [private:482930388]
2021-10-26 09:40:54,453 - Уровень INFO в logging.py.on_pre_process_error: Process update [ID:88022826]: [failed] (in 182 ms)
2021-10-26 09:40:54,453 - Уровень ERROR в web_protocol.py.log_exception: Error handling request
Traceback (most recent call last):
  File "E:\Koд\bot\venv\lib\site-packages\aiohttp\web_protocol.py", line 422, in _handle_request
    resp = await self._request_handler(request)
  File "E:\Koд\bot\venv\lib\site-packages\aiohttp\web_app.py", line 499, in _handle
    resp = await handler(request)
  File "E:\Koд\bot\venv\lib\site-packages\aiohttp\web_urldispatcher.py", line 948, in _iter
    resp = await method()
  File "E:\Koд\bot\venv\lib\site-packages\aiogram\dispatcher\webhook.py", line 139, in post
    results = await self.process_update(update)
  File "E:\Koд\bot\venv\lib\site-packages\aiogram\dispatcher\webhook.py", line 190, in process_update
    return fut.result()
  File "E:\Koд\bot\venv\lib\site-packages\aiogram\dispatcher\handler.py", line 116, in notify
    response = await handler_obj.handler(*args, **partial_data)
  File "E:\Koд\bot\venv\lib\site-packages\aiogram\dispatcher\dispatcher.py", line 259, in process_update
    return await self.message_handlers.notify(update.message)
  File "E:\Koд\bot\venv\lib\site-packages\aiogram\dispatcher\handler.py", line 116, in notify
    response = await handler_obj.handler(*args, **partial_data)
  File ".\main.py", line 178, in bot_message
    await bot.send_message(message.from_user.id, tech_anal.get('RU_anal'))
  File "E:\Koд\bot\venv\lib\site-packages\aiogram\bot\bot.py", line 314, in send_message
    result = await self.request(api.Methods.SEND_MESSAGE, payload)
  File "E:\Koд\bot\venv\lib\site-packages\aiogram\bot\base.py", line 208, in request
    return await api.make_request(self.session, self.server, self.__token, method, data, files,
  File "E:\Koд\bot\venv\lib\site-packages\aiogram\bot\api.py", line 140, in make_request
    return check_result(method, response.content_type, response.status, await response.text())
  File "E:\Koд\bot\venv\lib\site-packages\aiogram\bot\api.py", line 115, in check_result
    exceptions.BadRequest.detect(description)
  File "E:\Koд\bot\venv\lib\site-packages\aiogram\utils\exceptions.py", line 140, in detect
    raise err(cls.text or description)
aiogram.utils.exceptions.MessageIsTooLong: Message is too long
2021-10-26 09:40:54,457 - Уровень INFO в web_log.py.log: 127.0.0.1 [26/Oct/2021:06:40:54 +0000] "POST / HTTP/1.1" 500 250 "-" "-"
2021-10-26 09:40:59,164 - Уровень INFO в logging.py.on_pre_process_message: Received message [ID:1322] in chat [private:482930388]
2021-10-26 09:40:59,353 - Уровень INFO в logging.py.on_pre_process_error: Process update [ID:88022826]: [failed] (in 189 ms)
2021-10-26 09:40:59,353 - Уровень ERROR в web_protocol.py.log_exception: Error handling request
Traceback (most recent call last):
  File "E:\Koд\bot\venv\lib\site-packages\aiohttp\web_protocol.py", line 422, in _handle_request
    resp = await self._request_handler(request)
  File "E:\Koд\bot\venv\lib\site-packages\aiohttp\web_app.py", line 499, in _handle
    resp = await handler(request)
  File "E:\Koд\bot\venv\lib\site-packages\aiohttp\web_urldispatcher.py", line 948, in _iter
    resp = await method()
  File "E:\Koд\bot\venv\lib\site-packages\aiogram\dispatcher\webhook.py", line 139, in post
    results = await self.process_update(update)
  File "E:\Koд\bot\venv\lib\site-packages\aiogram\dispatcher\webhook.py", line 190, in process_update
    return fut.result()
  File "E:\Koд\bot\venv\lib\site-packages\aiogram\dispatcher\handler.py", line 116, in notify
    response = await handler_obj.handler(*args, **partial_data)
  File "E:\Koд\bot\venv\lib\site-packages\aiogram\dispatcher\dispatcher.py", line 259, in process_update
    return await self.message_handlers.notify(update.message)
  File "E:\Koд\bot\venv\lib\site-packages\aiogram\dispatcher\handler.py", line 116, in notify
    response = await handler_obj.handler(*args, **partial_data)
  File ".\main.py", line 178, in bot_message
    await bot.send_message(message.from_user.id, tech_anal.get('RU_anal'))
  File "E:\Koд\bot\venv\lib\site-packages\aiogram\bot\bot.py", line 314, in send_message
    result = await self.request(api.Methods.SEND_MESSAGE, payload)
  File "E:\Koд\bot\venv\lib\site-packages\aiogram\bot\base.py", line 208, in request
    return await api.make_request(self.session, self.server, self.__token, method, data, files,
  File "E:\Koд\bot\venv\lib\site-packages\aiogram\bot\api.py", line 140, in make_request
    return check_result(method, response.content_type, response.status, await response.text())
  File "E:\Koд\bot\venv\lib\site-packages\aiogram\bot\api.py", line 115, in check_result
    exceptions.BadRequest.detect(description)
  File "E:\Koд\bot\venv\lib\site-packages\aiogram\utils\exceptions.py", line 140, in detect
    raise err(cls.text or description)
aiogram.utils.exceptions.MessageIsTooLong: Message is too long
2021-10-26 09:40:59,356 - Уровень INFO в web_log.py.log: 127.0.0.1 [26/Oct/2021:06:40:59 +0000] "POST / HTTP/1.1" 500 250 "-" "-"
2021-10-26 09:41:08,056 - Уровень INFO в logging.py.on_pre_process_message: Received message [ID:1322] in chat [private:482930388]
2021-10-26 09:41:08,200 - Уровень INFO в logging.py.on_pre_process_error: Process update [ID:88022826]: [failed] (in 144 ms)
2021-10-26 09:41:08,200 - Уровень ERROR в web_protocol.py.log_exception: Error handling request
Traceback (most recent call last):
  File "E:\Koд\bot\venv\lib\site-packages\aiohttp\web_protocol.py", line 422, in _handle_request
    resp = await self._request_handler(request)
  File "E:\Koд\bot\venv\lib\site-packages\aiohttp\web_app.py", line 499, in _handle
    resp = await handler(request)
  File "E:\Koд\bot\venv\lib\site-packages\aiohttp\web_urldispatcher.py", line 948, in _iter
    resp = await method()
  File "E:\Koд\bot\venv\lib\site-packages\aiogram\dispatcher\webhook.py", line 139, in post
    results = await self.process_update(update)
  File "E:\Koд\bot\venv\lib\site-packages\aiogram\dispatcher\webhook.py", line 190, in process_update
    return fut.result()
  File "E:\Koд\bot\venv\lib\site-packages\aiogram\dispatcher\handler.py", line 116, in notify
    response = await handler_obj.handler(*args, **partial_data)
  File "E:\Koд\bot\venv\lib\site-packages\aiogram\dispatcher\dispatcher.py", line 259, in process_update
    return await self.message_handlers.notify(update.message)
  File "E:\Koд\bot\venv\lib\site-packages\aiogram\dispatcher\handler.py", line 116, in notify
    response = await handler_obj.handler(*args, **partial_data)
  File ".\main.py", line 178, in bot_message
    await bot.send_message(message.from_user.id, tech_anal.get('RU_anal'))
  File "E:\Koд\bot\venv\lib\site-packages\aiogram\bot\bot.py", line 314, in send_message
    result = await self.request(api.Methods.SEND_MESSAGE, payload)
  File "E:\Koд\bot\venv\lib\site-packages\aiogram\bot\base.py", line 208, in request
    return await api.make_request(self.session, self.server, self.__token, method, data, files,
  File "E:\Koд\bot\venv\lib\site-packages\aiogram\bot\api.py", line 140, in make_request
    return check_result(method, response.content_type, response.status, await response.text())
  File "E:\Koд\bot\venv\lib\site-packages\aiogram\bot\api.py", line 115, in check_result
    exceptions.BadRequest.detect(description)
  File "E:\Koд\bot\venv\lib\site-packages\aiogram\utils\exceptions.py", line 140, in detect
    raise err(cls.text or description)
aiogram.utils.exceptions.MessageIsTooLong: Message is too long
2021-10-26 09:41:08,208 - Уровень INFO в web_log.py.log: 127.0.0.1 [26/Oct/2021:06:41:08 +0000] "POST / HTTP/1.1" 500 250 "-" "-"
2021-10-26 09:41:23,758 - Уровень WARNING в main.py.on_shutdown: Shutting down..
2021-10-26 09:41:24,209 - Уровень WARNING в main.py.on_shutdown: Bye!
2021-10-26 09:41:39,091 - Уровень INFO в executor.py._welcome: Bot: CyberEvil [@cyber_evil_bot]
2021-10-26 09:41:39,398 - Уровень WARNING в executor.py._skip_updates: Updates were skipped successfully.
2021-10-26 09:41:40,253 - Уровень INFO в logging.py.on_pre_process_message: Received message [ID:1322] in chat [private:482930388]
2021-10-26 09:41:40,473 - Уровень INFO в logging.py.on_post_process_update: Process update [ID:88022826]: [success] (in 220 ms)
2021-10-26 09:41:40,474 - Уровень INFO в web_log.py.log: 127.0.0.1 [26/Oct/2021:06:41:40 +0000] "POST / HTTP/1.1" 200 158 "-" "-"
2021-10-26 09:41:56,128 - Уровень WARNING в main.py.on_shutdown: Shutting down..
2021-10-26 09:41:56,568 - Уровень WARNING в main.py.on_shutdown: Bye!
2021-10-26 09:41:58,629 - Уровень INFO в executor.py._welcome: Bot: CyberEvil [@cyber_evil_bot]
2021-10-26 09:41:59,917 - Уровень WARNING в executor.py._skip_updates: Updates were skipped successfully.
2021-10-26 09:42:06,124 - Уровень INFO в logging.py.on_pre_process_message: Received message [ID:1324] in chat [private:482930388]
2021-10-26 09:42:06,287 - Уровень INFO в logging.py.on_pre_process_error: Process update [ID:88022827]: [failed] (in 164 ms)
2021-10-26 09:42:06,287 - Уровень ERROR в web_protocol.py.log_exception: Error handling request
Traceback (most recent call last):
  File "E:\Koд\bot\venv\lib\site-packages\aiohttp\web_protocol.py", line 422, in _handle_request
    resp = await self._request_handler(request)
  File "E:\Koд\bot\venv\lib\site-packages\aiohttp\web_app.py", line 499, in _handle
    resp = await handler(request)
  File "E:\Koд\bot\venv\lib\site-packages\aiohttp\web_urldispatcher.py", line 948, in _iter
    resp = await method()
  File "E:\Koд\bot\venv\lib\site-packages\aiogram\dispatcher\webhook.py", line 139, in post
    results = await self.process_update(update)
  File "E:\Koд\bot\venv\lib\site-packages\aiogram\dispatcher\webhook.py", line 190, in process_update
    return fut.result()
  File "E:\Koд\bot\venv\lib\site-packages\aiogram\dispatcher\handler.py", line 116, in notify
    response = await handler_obj.handler(*args, **partial_data)
  File "E:\Koд\bot\venv\lib\site-packages\aiogram\dispatcher\dispatcher.py", line 259, in process_update
    return await self.message_handlers.notify(update.message)
  File "E:\Koд\bot\venv\lib\site-packages\aiogram\dispatcher\handler.py", line 116, in notify
    response = await handler_obj.handler(*args, **partial_data)
  File ".\main.py", line 178, in bot_message
    await bot.send_message(message.from_user.id, tech_anal.get('RU_anal'))
  File "E:\Koд\bot\venv\lib\site-packages\aiogram\bot\bot.py", line 314, in send_message
    result = await self.request(api.Methods.SEND_MESSAGE, payload)
  File "E:\Koд\bot\venv\lib\site-packages\aiogram\bot\base.py", line 208, in request
    return await api.make_request(self.session, self.server, self.__token, method, data, files,
  File "E:\Koд\bot\venv\lib\site-packages\aiogram\bot\api.py", line 140, in make_request
    return check_result(method, response.content_type, response.status, await response.text())
  File "E:\Koд\bot\venv\lib\site-packages\aiogram\bot\api.py", line 115, in check_result
    exceptions.BadRequest.detect(description)
  File "E:\Koд\bot\venv\lib\site-packages\aiogram\utils\exceptions.py", line 140, in detect
    raise err(cls.text or description)
aiogram.utils.exceptions.MessageIsTooLong: Message is too long
2021-10-26 09:42:06,304 - Уровень INFO в web_log.py.log: 127.0.0.1 [26/Oct/2021:06:42:06 +0000] "POST / HTTP/1.1" 500 250 "-" "-"
2021-10-26 09:42:06,996 - Уровень INFO в logging.py.on_pre_process_message: Received message [ID:1324] in chat [private:482930388]
2021-10-26 09:42:07,169 - Уровень INFO в logging.py.on_pre_process_error: Process update [ID:88022827]: [failed] (in 172 ms)
2021-10-26 09:42:07,169 - Уровень ERROR в web_protocol.py.log_exception: Error handling request
Traceback (most recent call last):
  File "E:\Koд\bot\venv\lib\site-packages\aiohttp\web_protocol.py", line 422, in _handle_request
    resp = await self._request_handler(request)
  File "E:\Koд\bot\venv\lib\site-packages\aiohttp\web_app.py", line 499, in _handle
    resp = await handler(request)
  File "E:\Koд\bot\venv\lib\site-packages\aiohttp\web_urldispatcher.py", line 948, in _iter
    resp = await method()
  File "E:\Koд\bot\venv\lib\site-packages\aiogram\dispatcher\webhook.py", line 139, in post
    results = await self.process_update(update)
  File "E:\Koд\bot\venv\lib\site-packages\aiogram\dispatcher\webhook.py", line 190, in process_update
    return fut.result()
  File "E:\Koд\bot\venv\lib\site-packages\aiogram\dispatcher\handler.py", line 116, in notify
    response = await handler_obj.handler(*args, **partial_data)
  File "E:\Koд\bot\venv\lib\site-packages\aiogram\dispatcher\dispatcher.py", line 259, in process_update
    return await self.message_handlers.notify(update.message)
  File "E:\Koд\bot\venv\lib\site-packages\aiogram\dispatcher\handler.py", line 116, in notify
    response = await handler_obj.handler(*args, **partial_data)
  File ".\main.py", line 178, in bot_message
    await bot.send_message(message.from_user.id, tech_anal.get('RU_anal'))
  File "E:\Koд\bot\venv\lib\site-packages\aiogram\bot\bot.py", line 314, in send_message
    result = await self.request(api.Methods.SEND_MESSAGE, payload)
  File "E:\Koд\bot\venv\lib\site-packages\aiogram\bot\base.py", line 208, in request
    return await api.make_request(self.session, self.server, self.__token, method, data, files,
  File "E:\Koд\bot\venv\lib\site-packages\aiogram\bot\api.py", line 140, in make_request
    return check_result(method, response.content_type, response.status, await response.text())
  File "E:\Koд\bot\venv\lib\site-packages\aiogram\bot\api.py", line 115, in check_result
    exceptions.BadRequest.detect(description)
  File "E:\Koд\bot\venv\lib\site-packages\aiogram\utils\exceptions.py", line 140, in detect
    raise err(cls.text or description)
aiogram.utils.exceptions.MessageIsTooLong: Message is too long
2021-10-26 09:42:07,172 - Уровень INFO в web_log.py.log: 127.0.0.1 [26/Oct/2021:06:42:07 +0000] "POST / HTTP/1.1" 500 250 "-" "-"
2021-10-26 09:42:09,875 - Уровень INFO в logging.py.on_pre_process_message: Received message [ID:1324] in chat [private:482930388]
2021-10-26 09:42:10,101 - Уровень INFO в logging.py.on_pre_process_error: Process update [ID:88022827]: [failed] (in 226 ms)
2021-10-26 09:42:10,102 - Уровень ERROR в web_protocol.py.log_exception: Error handling request
Traceback (most recent call last):
  File "E:\Koд\bot\venv\lib\site-packages\aiohttp\web_protocol.py", line 422, in _handle_request
    resp = await self._request_handler(request)
  File "E:\Koд\bot\venv\lib\site-packages\aiohttp\web_app.py", line 499, in _handle
    resp = await handler(request)
  File "E:\Koд\bot\venv\lib\site-packages\aiohttp\web_urldispatcher.py", line 948, in _iter
    resp = await method()
  File "E:\Koд\bot\venv\lib\site-packages\aiogram\dispatcher\webhook.py", line 139, in post
    results = await self.process_update(update)
  File "E:\Koд\bot\venv\lib\site-packages\aiogram\dispatcher\webhook.py", line 190, in process_update
    return fut.result()
  File "E:\Koд\bot\venv\lib\site-packages\aiogram\dispatcher\handler.py", line 116, in notify
    response = await handler_obj.handler(*args, **partial_data)
  File "E:\Koд\bot\venv\lib\site-packages\aiogram\dispatcher\dispatcher.py", line 259, in process_update
    return await self.message_handlers.notify(update.message)
  File "E:\Koд\bot\venv\lib\site-packages\aiogram\dispatcher\handler.py", line 116, in notify
    response = await handler_obj.handler(*args, **partial_data)
  File ".\main.py", line 178, in bot_message
    await bot.send_message(message.from_user.id, tech_anal.get('RU_anal'))
  File "E:\Koд\bot\venv\lib\site-packages\aiogram\bot\bot.py", line 314, in send_message
    result = await self.request(api.Methods.SEND_MESSAGE, payload)
  File "E:\Koд\bot\venv\lib\site-packages\aiogram\bot\base.py", line 208, in request
    return await api.make_request(self.session, self.server, self.__token, method, data, files,
  File "E:\Koд\bot\venv\lib\site-packages\aiogram\bot\api.py", line 140, in make_request
    return check_result(method, response.content_type, response.status, await response.text())
  File "E:\Koд\bot\venv\lib\site-packages\aiogram\bot\api.py", line 115, in check_result
    exceptions.BadRequest.detect(description)
  File "E:\Koд\bot\venv\lib\site-packages\aiogram\utils\exceptions.py", line 140, in detect
    raise err(cls.text or description)
aiogram.utils.exceptions.MessageIsTooLong: Message is too long
2021-10-26 09:42:10,104 - Уровень INFO в web_log.py.log: 127.0.0.1 [26/Oct/2021:06:42:09 +0000] "POST / HTTP/1.1" 500 250 "-" "-"
2021-10-26 09:42:14,802 - Уровень INFO в logging.py.on_pre_process_message: Received message [ID:1324] in chat [private:482930388]
2021-10-26 09:42:14,993 - Уровень INFO в logging.py.on_pre_process_error: Process update [ID:88022827]: [failed] (in 191 ms)
2021-10-26 09:42:14,993 - Уровень ERROR в web_protocol.py.log_exception: Error handling request
Traceback (most recent call last):
  File "E:\Koд\bot\venv\lib\site-packages\aiohttp\web_protocol.py", line 422, in _handle_request
    resp = await self._request_handler(request)
  File "E:\Koд\bot\venv\lib\site-packages\aiohttp\web_app.py", line 499, in _handle
    resp = await handler(request)
  File "E:\Koд\bot\venv\lib\site-packages\aiohttp\web_urldispatcher.py", line 948, in _iter
    resp = await method()
  File "E:\Koд\bot\venv\lib\site-packages\aiogram\dispatcher\webhook.py", line 139, in post
    results = await self.process_update(update)
  File "E:\Koд\bot\venv\lib\site-packages\aiogram\dispatcher\webhook.py", line 190, in process_update
    return fut.result()
  File "E:\Koд\bot\venv\lib\site-packages\aiogram\dispatcher\handler.py", line 116, in notify
    response = await handler_obj.handler(*args, **partial_data)
  File "E:\Koд\bot\venv\lib\site-packages\aiogram\dispatcher\dispatcher.py", line 259, in process_update
    return await self.message_handlers.notify(update.message)
  File "E:\Koд\bot\venv\lib\site-packages\aiogram\dispatcher\handler.py", line 116, in notify
    response = await handler_obj.handler(*args, **partial_data)
  File ".\main.py", line 178, in bot_message
    await bot.send_message(message.from_user.id, tech_anal.get('RU_anal'))
  File "E:\Koд\bot\venv\lib\site-packages\aiogram\bot\bot.py", line 314, in send_message
    result = await self.request(api.Methods.SEND_MESSAGE, payload)
  File "E:\Koд\bot\venv\lib\site-packages\aiogram\bot\base.py", line 208, in request
    return await api.make_request(self.session, self.server, self.__token, method, data, files,
  File "E:\Koд\bot\venv\lib\site-packages\aiogram\bot\api.py", line 140, in make_request
    return check_result(method, response.content_type, response.status, await response.text())
  File "E:\Koд\bot\venv\lib\site-packages\aiogram\bot\api.py", line 115, in check_result
    exceptions.BadRequest.detect(description)
  File "E:\Koд\bot\venv\lib\site-packages\aiogram\utils\exceptions.py", line 140, in detect
    raise err(cls.text or description)
aiogram.utils.exceptions.MessageIsTooLong: Message is too long
2021-10-26 09:42:14,995 - Уровень INFO в web_log.py.log: 127.0.0.1 [26/Oct/2021:06:42:14 +0000] "POST / HTTP/1.1" 500 250 "-" "-"
2021-10-26 09:42:23,686 - Уровень INFO в logging.py.on_pre_process_message: Received message [ID:1324] in chat [private:482930388]
2021-10-26 09:42:23,840 - Уровень INFO в logging.py.on_pre_process_error: Process update [ID:88022827]: [failed] (in 154 ms)
2021-10-26 09:42:23,840 - Уровень ERROR в web_protocol.py.log_exception: Error handling request
Traceback (most recent call last):
  File "E:\Koд\bot\venv\lib\site-packages\aiohttp\web_protocol.py", line 422, in _handle_request
    resp = await self._request_handler(request)
  File "E:\Koд\bot\venv\lib\site-packages\aiohttp\web_app.py", line 499, in _handle
    resp = await handler(request)
  File "E:\Koд\bot\venv\lib\site-packages\aiohttp\web_urldispatcher.py", line 948, in _iter
    resp = await method()
  File "E:\Koд\bot\venv\lib\site-packages\aiogram\dispatcher\webhook.py", line 139, in post
    results = await self.process_update(update)
  File "E:\Koд\bot\venv\lib\site-packages\aiogram\dispatcher\webhook.py", line 190, in process_update
    return fut.result()
  File "E:\Koд\bot\venv\lib\site-packages\aiogram\dispatcher\handler.py", line 116, in notify
    response = await handler_obj.handler(*args, **partial_data)
  File "E:\Koд\bot\venv\lib\site-packages\aiogram\dispatcher\dispatcher.py", line 259, in process_update
    return await self.message_handlers.notify(update.message)
  File "E:\Koд\bot\venv\lib\site-packages\aiogram\dispatcher\handler.py", line 116, in notify
    response = await handler_obj.handler(*args, **partial_data)
  File ".\main.py", line 178, in bot_message
    await bot.send_message(message.from_user.id, tech_anal.get('RU_anal'))
  File "E:\Koд\bot\venv\lib\site-packages\aiogram\bot\bot.py", line 314, in send_message
    result = await self.request(api.Methods.SEND_MESSAGE, payload)
  File "E:\Koд\bot\venv\lib\site-packages\aiogram\bot\base.py", line 208, in request
    return await api.make_request(self.session, self.server, self.__token, method, data, files,
  File "E:\Koд\bot\venv\lib\site-packages\aiogram\bot\api.py", line 140, in make_request
    return check_result(method, response.content_type, response.status, await response.text())
  File "E:\Koд\bot\venv\lib\site-packages\aiogram\bot\api.py", line 115, in check_result
    exceptions.BadRequest.detect(description)
  File "E:\Koд\bot\venv\lib\site-packages\aiogram\utils\exceptions.py", line 140, in detect
    raise err(cls.text or description)
aiogram.utils.exceptions.MessageIsTooLong: Message is too long
2021-10-26 09:42:23,848 - Уровень INFO в web_log.py.log: 127.0.0.1 [26/Oct/2021:06:42:23 +0000] "POST / HTTP/1.1" 500 250 "-" "-"
2021-10-26 09:42:40,546 - Уровень INFO в logging.py.on_pre_process_message: Received message [ID:1324] in chat [private:482930388]
2021-10-26 09:42:41,015 - Уровень INFO в logging.py.on_pre_process_error: Process update [ID:88022827]: [failed] (in 469 ms)
2021-10-26 09:42:41,015 - Уровень ERROR в web_protocol.py.log_exception: Error handling request
Traceback (most recent call last):
  File "E:\Koд\bot\venv\lib\site-packages\aiohttp\web_protocol.py", line 422, in _handle_request
    resp = await self._request_handler(request)
  File "E:\Koд\bot\venv\lib\site-packages\aiohttp\web_app.py", line 499, in _handle
    resp = await handler(request)
  File "E:\Koд\bot\venv\lib\site-packages\aiohttp\web_urldispatcher.py", line 948, in _iter
    resp = await method()
  File "E:\Koд\bot\venv\lib\site-packages\aiogram\dispatcher\webhook.py", line 139, in post
    results = await self.process_update(update)
  File "E:\Koд\bot\venv\lib\site-packages\aiogram\dispatcher\webhook.py", line 190, in process_update
    return fut.result()
  File "E:\Koд\bot\venv\lib\site-packages\aiogram\dispatcher\handler.py", line 116, in notify
    response = await handler_obj.handler(*args, **partial_data)
  File "E:\Koд\bot\venv\lib\site-packages\aiogram\dispatcher\dispatcher.py", line 259, in process_update
    return await self.message_handlers.notify(update.message)
  File "E:\Koд\bot\venv\lib\site-packages\aiogram\dispatcher\handler.py", line 116, in notify
    response = await handler_obj.handler(*args, **partial_data)
  File ".\main.py", line 178, in bot_message
    await bot.send_message(message.from_user.id, tech_anal.get('RU_anal'))
  File "E:\Koд\bot\venv\lib\site-packages\aiogram\bot\bot.py", line 314, in send_message
    result = await self.request(api.Methods.SEND_MESSAGE, payload)
  File "E:\Koд\bot\venv\lib\site-packages\aiogram\bot\base.py", line 208, in request
    return await api.make_request(self.session, self.server, self.__token, method, data, files,
  File "E:\Koд\bot\venv\lib\site-packages\aiogram\bot\api.py", line 140, in make_request
    return check_result(method, response.content_type, response.status, await response.text())
  File "E:\Koд\bot\venv\lib\site-packages\aiogram\bot\api.py", line 115, in check_result
    exceptions.BadRequest.detect(description)
  File "E:\Koд\bot\venv\lib\site-packages\aiogram\utils\exceptions.py", line 140, in detect
    raise err(cls.text or description)
aiogram.utils.exceptions.MessageIsTooLong: Message is too long
2021-10-26 09:42:41,019 - Уровень INFO в web_log.py.log: 127.0.0.1 [26/Oct/2021:06:42:40 +0000] "POST / HTTP/1.1" 500 250 "-" "-"
2021-10-26 09:42:49,511 - Уровень WARNING в main.py.on_shutdown: Shutting down..
2021-10-26 09:42:49,670 - Уровень WARNING в main.py.on_shutdown: Bye!
2021-10-26 09:43:02,699 - Уровень INFO в executor.py._welcome: Bot: CyberEvil [@cyber_evil_bot]
2021-10-26 09:43:02,988 - Уровень WARNING в executor.py._skip_updates: Updates were skipped successfully.
2021-10-26 09:43:03,847 - Уровень INFO в logging.py.on_pre_process_message: Received message [ID:1324] in chat [private:482930388]
2021-10-26 09:43:04,079 - Уровень INFO в logging.py.on_post_process_update: Process update [ID:88022827]: [success] (in 232 ms)
2021-10-26 09:43:04,089 - Уровень INFO в web_log.py.log: 127.0.0.1 [26/Oct/2021:06:43:03 +0000] "POST / HTTP/1.1" 200 158 "-" "-"
2021-10-26 10:43:07,754 - Уровень INFO в logging.py.on_pre_process_message: Received message [ID:1326] in chat [private:1364184778]
2021-10-26 10:43:08,326 - Уровень INFO в logging.py.on_post_process_update: Process update [ID:88022828]: [success] (in 572 ms)
2021-10-26 10:43:08,329 - Уровень INFO в web_log.py.log: 127.0.0.1 [26/Oct/2021:07:43:07 +0000] "POST / HTTP/1.1" 200 158 "-" "-"
2021-10-26 10:43:09,696 - Уровень INFO в logging.py.on_pre_process_message: Received message [ID:1328] in chat [private:1364184778]
2021-10-26 10:43:09,912 - Уровень INFO в logging.py.on_post_process_update: Process update [ID:88022829]: [success] (in 216 ms)
2021-10-26 10:43:09,914 - Уровень INFO в web_log.py.log: 127.0.0.1 [26/Oct/2021:07:43:09 +0000] "POST / HTTP/1.1" 200 158 "-" "-"
2021-10-26 10:43:13,454 - Уровень INFO в logging.py.on_pre_process_message: Received message [ID:1330] in chat [private:1364184778]
2021-10-26 10:43:13,677 - Уровень INFO в logging.py.on_post_process_update: Process update [ID:88022830]: [success] (in 224 ms)
2021-10-26 10:43:13,683 - Уровень INFO в web_log.py.log: 127.0.0.1 [26/Oct/2021:07:43:13 +0000] "POST / HTTP/1.1" 200 158 "-" "-"
2021-10-26 17:14:29,842 - Уровень WARNING в main.py.on_shutdown: Shutting down..
2021-10-26 17:14:30,484 - Уровень WARNING в main.py.on_shutdown: Bye!
2021-10-26 17:14:40,982 - Уровень INFO в executor.py._welcome: Bot: CyberEvil [@cyber_evil_bot]
2021-10-26 17:14:42,317 - Уровень WARNING в executor.py._skip_updates: Updates were skipped successfully.
2021-10-26 17:15:48,103 - Уровень INFO в logging.py.on_pre_process_message: Received message [ID:1332] in chat [private:317815278]
2021-10-26 17:15:48,639 - Уровень INFO в logging.py.on_post_process_update: Process update [ID:88022831]: [success] (in 536 ms)
2021-10-26 17:15:48,641 - Уровень INFO в web_log.py.log: 127.0.0.1 [26/Oct/2021:14:15:48 +0000] "POST / HTTP/1.1" 200 158 "-" "-"
2021-10-26 17:15:51,122 - Уровень INFO в logging.py.on_pre_process_message: Received message [ID:1334] in chat [private:317815278]
2021-10-26 17:15:51,474 - Уровень INFO в logging.py.on_post_process_update: Process update [ID:88022832]: [success] (in 353 ms)
2021-10-26 17:15:51,476 - Уровень INFO в web_log.py.log: 127.0.0.1 [26/Oct/2021:14:15:51 +0000] "POST / HTTP/1.1" 200 158 "-" "-"
2021-10-26 17:16:01,234 - Уровень INFO в logging.py.on_pre_process_message: Received message [ID:1336] in chat [private:317815278]
2021-10-26 17:16:01,929 - Уровень INFO в logging.py.on_post_process_update: Process update [ID:88022833]: [success] (in 695 ms)
2021-10-26 17:16:01,930 - Уровень INFO в web_log.py.log: 127.0.0.1 [26/Oct/2021:14:16:01 +0000] "POST / HTTP/1.1" 200 158 "-" "-"
2021-10-26 17:16:28,971 - Уровень INFO в logging.py.on_pre_process_message: Received message [ID:1338] in chat [private:317815278]
2021-10-26 17:16:29,458 - Уровень INFO в logging.py.on_post_process_update: Process update [ID:88022834]: [success] (in 487 ms)
2021-10-26 17:16:29,459 - Уровень INFO в web_log.py.log: 127.0.0.1 [26/Oct/2021:14:16:28 +0000] "POST / HTTP/1.1" 200 158 "-" "-"
2021-10-26 17:16:32,538 - Уровень INFO в logging.py.on_pre_process_message: Received message [ID:1340] in chat [private:317815278]
2021-10-26 17:16:32,780 - Уровень INFO в logging.py.on_post_process_update: Process update [ID:88022835]: [success] (in 242 ms)
2021-10-26 17:16:32,782 - Уровень INFO в web_log.py.log: 127.0.0.1 [26/Oct/2021:14:16:32 +0000] "POST / HTTP/1.1" 200 158 "-" "-"
2021-10-26 17:16:46,003 - Уровень INFO в logging.py.on_pre_process_message: Received message [ID:1342] in chat [private:317815278]
2021-10-26 17:16:46,182 - Уровень INFO в logging.py.on_post_process_update: Process update [ID:88022836]: [success] (in 179 ms)
2021-10-26 17:16:46,183 - Уровень INFO в web_log.py.log: 127.0.0.1 [26/Oct/2021:14:16:45 +0000] "POST / HTTP/1.1" 200 158 "-" "-"
2021-10-26 17:16:50,093 - Уровень INFO в logging.py.on_pre_process_message: Received message [ID:1344] in chat [private:317815278]
2021-10-26 17:16:50,359 - Уровень INFO в logging.py.on_post_process_update: Process update [ID:88022837]: [success] (in 266 ms)
2021-10-26 17:16:50,360 - Уровень INFO в web_log.py.log: 127.0.0.1 [26/Oct/2021:14:16:50 +0000] "POST / HTTP/1.1" 200 158 "-" "-"
2021-10-26 17:16:53,813 - Уровень INFO в logging.py.on_pre_process_message: Received message [ID:1346] in chat [private:317815278]
2021-10-26 17:16:54,039 - Уровень INFO в logging.py.on_post_process_update: Process update [ID:88022838]: [success] (in 225 ms)
2021-10-26 17:16:54,040 - Уровень INFO в web_log.py.log: 127.0.0.1 [26/Oct/2021:14:16:53 +0000] "POST / HTTP/1.1" 200 158 "-" "-"
2021-10-26 17:16:58,025 - Уровень INFO в logging.py.on_pre_process_message: Received message [ID:1348] in chat [private:317815278]
2021-10-26 17:16:58,289 - Уровень INFO в logging.py.on_post_process_update: Process update [ID:88022839]: [success] (in 265 ms)
2021-10-26 17:16:58,291 - Уровень INFO в web_log.py.log: 127.0.0.1 [26/Oct/2021:14:16:58 +0000] "POST / HTTP/1.1" 200 158 "-" "-"
2021-10-26 17:17:09,777 - Уровень INFO в logging.py.on_pre_process_message: Received message [ID:1350] in chat [private:317815278]
2021-10-26 17:17:09,977 - Уровень INFO в logging.py.on_post_process_update: Process update [ID:88022840]: [success] (in 200 ms)
2021-10-26 17:17:09,978 - Уровень INFO в web_log.py.log: 127.0.0.1 [26/Oct/2021:14:17:09 +0000] "POST / HTTP/1.1" 200 158 "-" "-"
2021-10-26 17:43:22,343 - Уровень INFO в logging.py.on_pre_process_message: Received message [ID:1352] in chat [private:482930388]
2021-10-26 17:43:23,364 - Уровень INFO в logging.py.on_post_process_update: Process update [ID:88022841]: [success] (in 1021 ms)
2021-10-26 17:43:23,366 - Уровень INFO в web_log.py.log: 127.0.0.1 [26/Oct/2021:14:43:22 +0000] "POST / HTTP/1.1" 200 158 "-" "-"
2021-10-26 17:43:45,313 - Уровень INFO в logging.py.on_pre_process_message: Received message [ID:1356] in chat [private:482930388]
2021-10-26 17:43:46,399 - Уровень INFO в logging.py.on_post_process_update: Process update [ID:88022842]: [success] (in 1087 ms)
2021-10-26 17:43:46,400 - Уровень INFO в web_log.py.log: 127.0.0.1 [26/Oct/2021:14:43:45 +0000] "POST / HTTP/1.1" 200 158 "-" "-"
2021-10-26 17:45:21,753 - Уровень INFO в logging.py.on_pre_process_edited_message: Received edited message [ID:1356] in chat [private:482930388]
2021-10-26 17:45:21,754 - Уровень INFO в logging.py.on_post_process_update: Process update [ID:88022843]: [success] (in 1 ms)
2021-10-26 17:45:21,756 - Уровень INFO в web_log.py.log: 127.0.0.1 [26/Oct/2021:14:45:21 +0000] "POST / HTTP/1.1" 200 158 "-" "-"
2021-10-26 17:45:28,840 - Уровень INFO в logging.py.on_pre_process_message: Received message [ID:1360] in chat [private:482930388]
2021-10-26 17:45:29,793 - Уровень INFO в logging.py.on_post_process_update: Process update [ID:88022844]: [success] (in 953 ms)
2021-10-26 17:45:29,794 - Уровень INFO в web_log.py.log: 127.0.0.1 [26/Oct/2021:14:45:28 +0000] "POST / HTTP/1.1" 200 158 "-" "-"
2021-10-26 17:47:30,275 - Уровень INFO в logging.py.on_pre_process_message: Received message [ID:1364] in chat [private:482930388]
2021-10-26 17:47:31,257 - Уровень INFO в logging.py.on_post_process_update: Process update [ID:88022845]: [success] (in 982 ms)
2021-10-26 17:47:31,258 - Уровень INFO в web_log.py.log: 127.0.0.1 [26/Oct/2021:14:47:30 +0000] "POST / HTTP/1.1" 200 158 "-" "-"
2021-10-26 17:48:10,917 - Уровень INFO в logging.py.on_pre_process_message: Received message [ID:1368] in chat [private:482930388]
2021-10-26 17:48:11,849 - Уровень INFO в logging.py.on_post_process_update: Process update [ID:88022846]: [success] (in 932 ms)
2021-10-26 17:48:11,851 - Уровень INFO в web_log.py.log: 127.0.0.1 [26/Oct/2021:14:48:10 +0000] "POST / HTTP/1.1" 200 158 "-" "-"
2021-10-26 17:49:27,320 - Уровень INFO в logging.py.on_pre_process_message: Received message [ID:1372] in chat [private:482930388]
2021-10-26 17:49:28,232 - Уровень INFO в logging.py.on_post_process_update: Process update [ID:88022847]: [success] (in 912 ms)
2021-10-26 17:49:28,233 - Уровень INFO в web_log.py.log: 127.0.0.1 [26/Oct/2021:14:49:27 +0000] "POST / HTTP/1.1" 200 158 "-" "-"
2021-10-26 17:50:18,018 - Уровень INFO в logging.py.on_pre_process_message: Received message [ID:1376] in chat [private:482930388]
2021-10-26 17:50:18,946 - Уровень INFO в logging.py.on_post_process_update: Process update [ID:88022848]: [success] (in 929 ms)
2021-10-26 17:50:18,948 - Уровень INFO в web_log.py.log: 127.0.0.1 [26/Oct/2021:14:50:18 +0000] "POST / HTTP/1.1" 200 158 "-" "-"
2021-10-26 17:51:15,786 - Уровень INFO в logging.py.on_pre_process_message: Received message [ID:1380] in chat [private:482930388]
2021-10-26 17:51:16,627 - Уровень INFO в logging.py.on_post_process_update: Process update [ID:88022849]: [success] (in 841 ms)
2021-10-26 17:51:16,628 - Уровень INFO в web_log.py.log: 127.0.0.1 [26/Oct/2021:14:51:15 +0000] "POST / HTTP/1.1" 200 158 "-" "-"
2021-10-26 17:52:33,353 - Уровень INFO в logging.py.on_pre_process_message: Received message [ID:1384] in chat [private:482930388]
2021-10-26 17:52:34,490 - Уровень INFO в logging.py.on_post_process_update: Process update [ID:88022850]: [success] (in 1136 ms)
2021-10-26 17:52:34,491 - Уровень INFO в web_log.py.log: 127.0.0.1 [26/Oct/2021:14:52:33 +0000] "POST / HTTP/1.1" 200 158 "-" "-"
2021-10-26 17:53:03,233 - Уровень INFO в logging.py.on_pre_process_message: Received message [ID:1388] in chat [private:482930388]
2021-10-26 17:53:04,228 - Уровень INFO в logging.py.on_post_process_update: Process update [ID:88022851]: [success] (in 996 ms)
2021-10-26 17:53:04,229 - Уровень INFO в web_log.py.log: 127.0.0.1 [26/Oct/2021:14:53:03 +0000] "POST / HTTP/1.1" 200 158 "-" "-"
2021-10-26 17:53:16,273 - Уровень INFO в logging.py.on_pre_process_message: Received message [ID:1392] in chat [private:482930388]
2021-10-26 17:53:17,326 - Уровень INFO в logging.py.on_post_process_update: Process update [ID:88022852]: [success] (in 1053 ms)
2021-10-26 17:53:17,328 - Уровень INFO в web_log.py.log: 127.0.0.1 [26/Oct/2021:14:53:16 +0000] "POST / HTTP/1.1" 200 158 "-" "-"
2021-10-26 17:53:42,325 - Уровень INFO в logging.py.on_pre_process_message: Received message [ID:1396] in chat [private:482930388]
2021-10-26 17:53:43,263 - Уровень INFO в logging.py.on_post_process_update: Process update [ID:88022853]: [success] (in 937 ms)
2021-10-26 17:53:43,264 - Уровень INFO в web_log.py.log: 127.0.0.1 [26/Oct/2021:14:53:42 +0000] "POST / HTTP/1.1" 200 158 "-" "-"
2021-10-26 18:02:53,495 - Уровень INFO в logging.py.on_pre_process_message: Received message [ID:1400] in chat [private:482930388]
2021-10-26 18:02:53,496 - Уровень INFO в logging.py.on_post_process_update: Process update [ID:88022854]: [success] (in 1 ms)
2021-10-26 18:02:53,497 - Уровень INFO в web_log.py.log: 127.0.0.1 [26/Oct/2021:15:02:53 +0000] "POST / HTTP/1.1" 200 158 "-" "-"
2021-10-26 18:09:26,029 - Уровень INFO в logging.py.on_pre_process_edited_message: Received edited message [ID:1400] in chat [private:482930388]
2021-10-26 18:09:26,029 - Уровень INFO в logging.py.on_post_process_update: Process update [ID:88022855]: [success] (in 1 ms)
2021-10-26 18:09:26,031 - Уровень INFO в web_log.py.log: 127.0.0.1 [26/Oct/2021:15:09:26 +0000] "POST / HTTP/1.1" 200 158 "-" "-"
2021-10-26 18:31:57,999 - Уровень WARNING в main.py.on_shutdown: Shutting down..
